Workbook

Sheet Cover
B2: NORTHSTAR HEALTH | Monthly FP&A Package
B3: Illustrative work product — May 2026
B5: Prepared by Mark Kempa · Demonstration of an AI-assisted FP&A workflow
B7: What this is | C7: A realistic monthly close & reporting package for a fictional Series B multi-site healthcare provider. Figures are illustrative, not from any real company.
B8: How AI was used | C8: Claude helped (1) structure the model and regional build, (2) draft the variance narrative from the data, and (3) build the financing / Series B-timing logic. A human reviews every number and sentence before it reaches leadership.
B9: Tabs | C9: P&L (Actual vs Budget) · KPIs & Unit Economics · Regions (revenue by geography, with expansion toggles) · Labor Model (hybrid in-person + telehealth) · Financing & Runway (Series B timing, equity vs. venture debt) · Variance Narrative.
B10: Color key | C10: Blue = input/assumption you can change. Black = formula. Change a blue cell and the model recalculates.
B12: Note | C12: Illustrative figures created to showcase method and output quality. $ in thousands unless noted.

Sheet P&L
B2: Income Statement — Actual vs. Budget ($ in 000s)
B3: Northstar Health (Illustrative) · May 2026
C4: CURRENT MONTH (May) | H4: YEAR TO DATE (Jan–May)
B5: $ in 000s | C5: Actual | D5: Budget | E5: Var $ | F5: Var % | H5: Actual | I5: Budget | J5: Var $ | K5: Var %
B6: Revenue
B7: Patient service revenue | C7: 3980 | D7: 4200 | E7: =C7-D7 -> -220 | F7: =IF(D7=0,"-",E7/D7) -> -0.052380952 | H7: 19850 | I7: 20800 | J7: =H7-I7 -> -950 | K7: =IF(I7=0,"-",J7/I7) -> -0.045673077
B8: Capitation & value-based | C8: 1240 | D8: 1180 | E8: =C8-D8 -> 60 | F8: =IF(D8=0,"-",E8/D8) -> 0.050847458 | H8: 6010 | I8: 5900 | J8: =H8-I8 -> 110 | K8: =IF(I8=0,"-",J8/I8) -> 0.018644068
B9: Other revenue | C9: 200 | D9: 220 | E9: =C9-D9 -> -20 | F9: =IF(D9=0,"-",E9/D9) -> -0.090909091 | H9: 1050 | I9: 1100 | J9: =H9-I9 -> -50 | K9: =IF(I9=0,"-",J9/I9) -> -0.045454545
B10: Total revenue | C10: =C7+C8+C9 -> 5420 | D10: =D7+D8+D9 -> 5600 | E10: =C10-D10 -> -180 | F10: =IF(D10=0,"-",E10/D10) -> -0.032142857 | H10: =H7+H8+H9 -> 26910 | I10: =I7+I8+I9 -> 27800 | J10: =H10-I10 -> -890 | K10: =IF(I10=0,"-",J10/I10) -> -0.032014388
B12: Direct costs (COGS)
B13: Clinical labor | C13: 2760 | D13: 2650 | E13: =C13-D13 -> 110 | F13: =IF(D13=0,"-",E13/D13) -> 0.041509434 | H13: 13400 | I13: 13050 | J13: =H13-I13 -> 350 | K13: =IF(I13=0,"-",J13/I13) -> 0.026819923
B14: Medical supplies | C14: 520 | D14: 500 | E14: =C14-D14 -> 20 | F14: =IF(D14=0,"-",E14/D14) -> 0.04 | H14: 2540 | I14: 2480 | J14: =H14-I14 -> 60 | K14: =IF(I14=0,"-",J14/I14) -> 0.024193548
B15: Facilities (clinical) | C15: 470 | D15: 460 | E15: =C15-D15 -> 10 | F15: =IF(D15=0,"-",E15/D15) -> 0.02173913 | H15: 2330 | I15: 2300 | J15: =H15-I15 -> 30 | K15: =IF(I15=0,"-",J15/I15) -> 0.013043478
B16: Total direct costs | C16: =C13+C14+C15 -> 3750 | D16: =D13+D14+D15 -> 3610 | E16: =C16-D16 -> 140 | F16: =IF(D16=0,"-",E16/D16) -> 0.038781163 | H16: =H13+H14+H15 -> 18270 | I16: =I13+I14+I15 -> 17830 | J16: =H16-I16 -> 440 | K16: =IF(I16=0,"-",J16/I16) -> 0.02467751
B17: Gross profit | C17: =C10-C16 -> 1670 | D17: =D10-D16 -> 1990 | E17: =C17-D17 -> -320 | F17: =IF(D17=0,"-",E17/D17) -> -0.16080402 | H17: =H10-H16 -> 8640 | I17: =I10-I16 -> 9970 | J17: =H17-I17 -> -1330 | K17: =IF(I17=0,"-",J17/I17) -> -0.1334002
B18: Gross margin % | C18: =IF(C10=0,"-",C17/C10) -> 0.30811808 | D18: =IF(D10=0,"-",D17/D10) -> 0.35535714 | H18: =IF(H10=0,"-",H17/H10) -> 0.32107023 | I18: =IF(I10=0,"-",I17/I10) -> 0.35863309
B20: Operating expenses
B21: Sales & marketing | C21: 410 | D21: 380 | E21: =C21-D21 -> 30 | F21: =IF(D21=0,"-",E21/D21) -> 0.078947368 | H21: 1980 | I21: 1900 | J21: =H21-I21 -> 80 | K21: =IF(I21=0,"-",J21/I21) -> 0.042105263
B22: General & administrative | C22: 720 | D22: 700 | E22: =C22-D22 -> 20 | F22: =IF(D22=0,"-",E22/D22) -> 0.028571429 | H22: 3560 | I22: 3500 | J22: =H22-I22 -> 60 | K22: =IF(I22=0,"-",J22/I22) -> 0.017142857
B23: Technology & R&D | C23: 250 | D23: 240 | E23: =C23-D23 -> 10 | F23: =IF(D23=0,"-",E23/D23) -> 0.041666667 | H23: 1230 | I23: 1200 | J23: =H23-I23 -> 30 | K23: =IF(I23=0,"-",J23/I23) -> 0.025
B24: Total operating expenses | C24: =C21+C22+C23 -> 1380 | D24: =D21+D22+D23 -> 1320 | E24: =C24-D24 -> 60 | F24: =IF(D24=0,"-",E24/D24) -> 0.045454545 | H24: =H21+H22+H23 -> 6770 | I24: =I21+I22+I23 -> 6600 | J24: =H24-I24 -> 170 | K24: =IF(I24=0,"-",J24/I24) -> 0.025757576
B26: EBITDA | C26: =C17-C24 -> 290 | D26: =D17-D24 -> 670 | E26: =C26-D26 -> -380 | F26: =IF(D26=0,"-",E26/D26) -> -0.56716418 | H26: =H17-H24 -> 1870 | I26: =I17-I24 -> 3370 | J26: =H26-I26 -> -1500 | K26: =IF(I26=0,"-",J26/I26) -> -0.44510386
B27: EBITDA margin % | C27: =IF(C10=0,"-",C26/C10) -> 0.053505535 | D27: =IF(D10=0,"-",D26/D10) -> 0.11964286 | H27: =IF(H10=0,"-",H26/H10) -> 0.069490896 | I27: =IF(I10=0,"-",I26/I10) -> 0.12122302
B29: Convention: variance = Actual − Budget. On expense lines a positive variance is an overspend (unfavorable).

Sheet KPIs & Unit Economics
B2: KPIs & Unit Economics — May 2026
B3: Operational drivers (blue) feed the per-unit metrics below.
B5: Operating Drivers
B6: Metric | C6: Actual | D6: Budget | E6: Var | F6: AI flag | H6: Assumptions
B7: Patient visits | C7: 18200 | D7: 18600 | E7: =C7-D7 -> -400 | F7: =IF(C7<D7*0.98,"Watch","On track") -> Watch | H7: Avg patient lifetime (months) | J7: 30
B8: Active patients | C8: 14500 | D8: 14600 | E8: =C8-D8 -> -100 | F8: =IF(C8<D8*0.98,"Watch","On track") -> On track
B9: New patients (month) | C9: 1120 | D9: 1200 | E9: =C9-D9 -> -80 | F9: =IF(C9<D9*0.98,"Watch","On track") -> Watch
B10: Sites / centers open | C10: 12 | D10: 12 | E10: =C10-D10 -> 0 | F10: =IF(C10<D10*0.98,"Watch","On track") -> On track
B12: Unit Economics
B13: Metric | C13: Actual | D13: Budget | E13: Var | F13: Unit
B14: Net revenue per visit | C14: ='P&L'!C10*1000/C7 -> 297.8022 | D14: ='P&L'!D10*1000/D7 -> 301.07527 | E14: =C14-D14 -> -3.273071 | F14: $/visit
B15: Direct cost per visit | C15: ='P&L'!C16*1000/C7 -> 206.04396 | D15: ='P&L'!D16*1000/D7 -> 194.08602 | E15: =C15-D15 -> 11.957935 | F15: $/visit
B16: Contribution per visit | C16: =C14-C15 -> 91.758242 | D16: =D14-D15 -> 106.98925 | E16: =C16-D16 -> -15.231006 | F16: $/visit
B17: Revenue per active patient / mo | C17: ='P&L'!C10*1000/C8 -> 373.7931 | D17: ='P&L'!D10*1000/D8 -> 383.56164 | E17: =C17-D17 -> -9.7685404 | F17: $/patient
B18: Customer acquisition cost (CAC) | C18: ='P&L'!C21*1000/C9 -> 366.07143 | D18: ='P&L'!D21*1000/D9 -> 316.66667 | E18: =C18-D18 -> 49.404762 | F18: $/new pt
B19: Patient lifetime value (LTV) | C19: =C17*'P&L'!C17/'P&L'!C10*$J$7 -> 3455.1724 | D19: =D17*'P&L'!D17/'P&L'!D10*$J$7 -> 4089.0411 | E19: =C19-D19 -> -633.86868 | F19: $ (est.)
B20: LTV / CAC | C20: =C19/C18 -> 9.4385198 | D20: =D19/D18 -> 12.912761 | E20: =C20-D20 -> -3.4742416 | F20: ratio
B21: Revenue per site / mo | C21: ='P&L'!C10/C10 -> 451.66667 | D21: ='P&L'!D10/D10 -> 466.66667 | E21: =C21-D21 -> -15 | F21: $000s
B23: LTV = (revenue per active patient/mo) × gross margin % × avg lifetime. Illustrative.

Sheet Regions
B2: Revenue by Region — Build & Expansion Toggles ($000s)
B3: Flip a region's Active toggle to 1 to bring it online. Existing markets reconcile to the May P&L.
B5: Region | C5: Active (1/0) | D5: Launch mo | E5: Mo-0 rev | F5: MoM growth | G5: Gross margin | H5: Launch capex | I5: Ramp opex/mo | J5: Ramp mos
B6: West (existing) | C6: 1 | D6: 0 | E6: 2400 | F6: 0.018 | G6: 0.32 | H6: 0 | I6: 0 | J6: 0
B7: Mountain (existing) | C7: 1 | D7: 0 | E7: 1900 | F7: 0.02 | G7: 0.305 | H7: 0 | I7: 0 | J7: 0
B8: Midwest (existing) | C8: 1 | D8: 0 | E8: 1120 | F8: 0.022 | G8: 0.29 | H8: 0 | I8: 0 | J8: 0
B9: Southeast (expansion) | C9: 0 | D9: 6 | E9: 800 | F9: 0.04 | G9: 0.29 | H9: 1800 | I9: 650 | J9: 8
B10: Northeast (expansion) | C10: 0 | D10: 9 | E10: 700 | F10: 0.04 | G10: 0.29 | H10: 1600 | I10: 600 | J10: 8
B11: Active regions / Mo-0 revenue | C11: =SUM(C6:C10) -> 3 | E11: =SUMPRODUCT(C6:C10,E6:E10) -> 5420
B13: Monthly build ($000s) | C13: M0 | D13: M1 | E13: M2 | F13: M3 | G13: M4 | H13: M5 | I13: M6 | J13: M7 | K13: M8 | L13: M9 | M13: M10 | N13: M11 | O13: M12 | P13: M13 | Q13: M14 | R13: M15 | S13: M16 | T13: M17 | U13: M18 | V13: M19 | W13: M20 | X13: M21 | Y13: M22 | Z13: M23 | AA13: M24
B14: West (existing) | C14: =IF(AND($C$6=1,(COLUMN()-3)>=$D$6),$E$6*(1+$F$6)^((COLUMN()-3)-$D$6),0) -> 2400 | D14: =IF(AND($C$6=1,(COLUMN()-3)>=$D$6),$E$6*(1+$F$6)^((COLUMN()-3)-$D$6),0) -> 2443.2 | E14: =IF(AND($C$6=1,(COLUMN()-3)>=$D$6),$E$6*(1+$F$6)^((COLUMN()-3)-$D$6),0) -> 2487.1776 | F14: =IF(AND($C$6=1,(COLUMN()-3)>=$D$6),$E$6*(1+$F$6)^((COLUMN()-3)-$D$6),0) -> 2531.9468 | G14: =IF(AND($C$6=1,(COLUMN()-3)>=$D$6),$E$6*(1+$F$6)^((COLUMN()-3)-$D$6),0) -> 2577.5218 | H14: =IF(AND($C$6=1,(COLUMN()-3)>=$D$6),$E$6*(1+$F$6)^((COLUMN()-3)-$D$6),0) -> 2623.9172 | I14: =IF(AND($C$6=1,(COLUMN()-3)>=$D$6),$E$6*(1+$F$6)^((COLUMN()-3)-$D$6),0) -> 2671.1477 | J14: =IF(AND($C$6=1,(COLUMN()-3)>=$D$6),$E$6*(1+$F$6)^((COLUMN()-3)-$D$6),0) -> 2719.2284 | ... AA14: =IF(AND($C$6=1,(COLUMN()-3)>=$D$6),$E$6*(1+$F$6)^((COLUMN()-3)-$D$6),0) -> 3682.6285
B15: Mountain (existing) | C15: =IF(AND($C$7=1,(COLUMN()-3)>=$D$7),$E$7*(1+$F$7)^((COLUMN()-3)-$D$7),0) -> 1900 | D15: =IF(AND($C$7=1,(COLUMN()-3)>=$D$7),$E$7*(1+$F$7)^((COLUMN()-3)-$D$7),0) -> 1938 | E15: =IF(AND($C$7=1,(COLUMN()-3)>=$D$7),$E$7*(1+$F$7)^((COLUMN()-3)-$D$7),0) -> 1976.76 | F15: =IF(AND($C$7=1,(COLUMN()-3)>=$D$7),$E$7*(1+$F$7)^((COLUMN()-3)-$D$7),0) -> 2016.2952 | G15: =IF(AND($C$7=1,(COLUMN()-3)>=$D$7),$E$7*(1+$F$7)^((COLUMN()-3)-$D$7),0) -> 2056.6211 | H15: =IF(AND($C$7=1,(COLUMN()-3)>=$D$7),$E$7*(1+$F$7)^((COLUMN()-3)-$D$7),0) -> 2097.7535 | I15: =IF(AND($C$7=1,(COLUMN()-3)>=$D$7),$E$7*(1+$F$7)^((COLUMN()-3)-$D$7),0) -> 2139.7086 | J15: =IF(AND($C$7=1,(COLUMN()-3)>=$D$7),$E$7*(1+$F$7)^((COLUMN()-3)-$D$7),0) -> 2182.5028 | ... AA15: =IF(AND($C$7=1,(COLUMN()-3)>=$D$7),$E$7*(1+$F$7)^((COLUMN()-3)-$D$7),0) -> 3056.0308
B16: Midwest (existing) | C16: =IF(AND($C$8=1,(COLUMN()-3)>=$D$8),$E$8*(1+$F$8)^((COLUMN()-3)-$D$8),0) -> 1120 | D16: =IF(AND($C$8=1,(COLUMN()-3)>=$D$8),$E$8*(1+$F$8)^((COLUMN()-3)-$D$8),0) -> 1144.64 | E16: =IF(AND($C$8=1,(COLUMN()-3)>=$D$8),$E$8*(1+$F$8)^((COLUMN()-3)-$D$8),0) -> 1169.8221 | F16: =IF(AND($C$8=1,(COLUMN()-3)>=$D$8),$E$8*(1+$F$8)^((COLUMN()-3)-$D$8),0) -> 1195.5582 | G16: =IF(AND($C$8=1,(COLUMN()-3)>=$D$8),$E$8*(1+$F$8)^((COLUMN()-3)-$D$8),0) -> 1221.8604 | H16: =IF(AND($C$8=1,(COLUMN()-3)>=$D$8),$E$8*(1+$F$8)^((COLUMN()-3)-$D$8),0) -> 1248.7414 | I16: =IF(AND($C$8=1,(COLUMN()-3)>=$D$8),$E$8*(1+$F$8)^((COLUMN()-3)-$D$8),0) -> 1276.2137 | J16: =IF(AND($C$8=1,(COLUMN()-3)>=$D$8),$E$8*(1+$F$8)^((COLUMN()-3)-$D$8),0) -> 1304.2904 | ... AA16: =IF(AND($C$8=1,(COLUMN()-3)>=$D$8),$E$8*(1+$F$8)^((COLUMN()-3)-$D$8),0) -> 1888.1632
B17: Southeast (expansion) | C17: =IF(AND($C$9=1,(COLUMN()-3)>=$D$9),$E$9*(1+$F$9)^((COLUMN()-3)-$D$9),0) -> 0 | D17: =IF(AND($C$9=1,(COLUMN()-3)>=$D$9),$E$9*(1+$F$9)^((COLUMN()-3)-$D$9),0) -> 0 | E17: =IF(AND($C$9=1,(COLUMN()-3)>=$D$9),$E$9*(1+$F$9)^((COLUMN()-3)-$D$9),0) -> 0 | F17: =IF(AND($C$9=1,(COLUMN()-3)>=$D$9),$E$9*(1+$F$9)^((COLUMN()-3)-$D$9),0) -> 0 | G17: =IF(AND($C$9=1,(COLUMN()-3)>=$D$9),$E$9*(1+$F$9)^((COLUMN()-3)-$D$9),0) -> 0 | H17: =IF(AND($C$9=1,(COLUMN()-3)>=$D$9),$E$9*(1+$F$9)^((COLUMN()-3)-$D$9),0) -> 0 | I17: =IF(AND($C$9=1,(COLUMN()-3)>=$D$9),$E$9*(1+$F$9)^((COLUMN()-3)-$D$9),0) -> 0 | J17: =IF(AND($C$9=1,(COLUMN()-3)>=$D$9),$E$9*(1+$F$9)^((COLUMN()-3)-$D$9),0) -> 0 | ... AA17: =IF(AND($C$9=1,(COLUMN()-3)>=$D$9),$E$9*(1+$F$9)^((COLUMN()-3)-$D$9),0) -> 0
B18: Northeast (expansion) | C18: =IF(AND($C$10=1,(COLUMN()-3)>=$D$10),$E$10*(1+$F$10)^((COLUMN()-3)-$D$10),0) -> 0 | D18: =IF(AND($C$10=1,(COLUMN()-3)>=$D$10),$E$10*(1+$F$10)^((COLUMN()-3)-$D$10),0) -> 0 | E18: =IF(AND($C$10=1,(COLUMN()-3)>=$D$10),$E$10*(1+$F$10)^((COLUMN()-3)-$D$10),0) -> 0 | F18: =IF(AND($C$10=1,(COLUMN()-3)>=$D$10),$E$10*(1+$F$10)^((COLUMN()-3)-$D$10),0) -> 0 | G18: =IF(AND($C$10=1,(COLUMN()-3)>=$D$10),$E$10*(1+$F$10)^((COLUMN()-3)-$D$10),0) -> 0 | H18: =IF(AND($C$10=1,(COLUMN()-3)>=$D$10),$E$10*(1+$F$10)^((COLUMN()-3)-$D$10),0) -> 0 | I18: =IF(AND($C$10=1,(COLUMN()-3)>=$D$10),$E$10*(1+$F$10)^((COLUMN()-3)-$D$10),0) -> 0 | J18: =IF(AND($C$10=1,(COLUMN()-3)>=$D$10),$E$10*(1+$F$10)^((COLUMN()-3)-$D$10),0) -> 0 | ... AA18: =IF(AND($C$10=1,(COLUMN()-3)>=$D$10),$E$10*(1+$F$10)^((COLUMN()-3)-$D$10),0) -> 0
B19: Total revenue | C19: =SUM(C14:C18) -> 5420 | D19: =SUM(D14:D18) -> 5525.84 | E19: =SUM(E14:E18) -> 5633.7597 | F19: =SUM(F14:F18) -> 5743.8002 | G19: =SUM(G14:G18) -> 5856.0034 | H19: =SUM(H14:H18) -> 5970.4121 | I19: =SUM(I14:I18) -> 6087.07 | J19: =SUM(J14:J18) -> 6206.0216 | ... AA19: =SUM(AA14:AA18) -> 8626.8225
B20: Gross profit | C20: =SUMPRODUCT(C14:C18,$G$6:$G$10) -> 1672.3 | D20: =SUMPRODUCT(D14:D18,$G$6:$G$10) -> 1704.8596 | E20: =SUMPRODUCT(E14:E18,$G$6:$G$10) -> 1738.057 | F20: =SUMPRODUCT(F14:F18,$G$6:$G$10) -> 1771.9049 | G20: =SUMPRODUCT(G14:G18,$G$6:$G$10) -> 1806.416 | H20: =SUMPRODUCT(H14:H18,$G$6:$G$10) -> 1841.6033 | I20: =SUMPRODUCT(I14:I18,$G$6:$G$10) -> 1877.4804 | J20: =SUMPRODUCT(J14:J18,$G$6:$G$10) -> 1914.0606 | ... AA20: =SUMPRODUCT(AA14:AA18,$G$6:$G$10) -> 2658.0978
B21: Blended gross margin % | C21: =IF(C19=0,0,C20/C19) -> 0.30854244 | D21: =IF(D19=0,0,D20/D19) -> 0.30852497 | E21: =IF(E19=0,0,E20/E19) -> 0.30850749 | F21: =IF(F19=0,0,F20/F19) -> 0.30848999 | G21: =IF(G19=0,0,G20/G19) -> 0.30847249 | H21: =IF(H19=0,0,H20/H19) -> 0.30845498 | I21: =IF(I19=0,0,I20/I19) -> 0.30843745 | J21: =IF(J19=0,0,J20/J19) -> 0.30841992 | ... AA21: =IF(AA19=0,0,AA20/AA19) -> 0.30812015
B22: Expansion launch capex | C22: =SUMPRODUCT(($C$6:$C$10)*((COLUMN()-3)=$D$6:$D$10)*($H$6:$H$10)) -> 0 | D22: =SUMPRODUCT(($C$6:$C$10)*((COLUMN()-3)=$D$6:$D$10)*($H$6:$H$10)) -> 0 | E22: =SUMPRODUCT(($C$6:$C$10)*((COLUMN()-3)=$D$6:$D$10)*($H$6:$H$10)) -> 0 | F22: =SUMPRODUCT(($C$6:$C$10)*((COLUMN()-3)=$D$6:$D$10)*($H$6:$H$10)) -> 0 | G22: =SUMPRODUCT(($C$6:$C$10)*((COLUMN()-3)=$D$6:$D$10)*($H$6:$H$10)) -> 0 | H22: =SUMPRODUCT(($C$6:$C$10)*((COLUMN()-3)=$D$6:$D$10)*($H$6:$H$10)) -> 0 | I22: =SUMPRODUCT(($C$6:$C$10)*((COLUMN()-3)=$D$6:$D$10)*($H$6:$H$10)) -> 0 | J22: =SUMPRODUCT(($C$6:$C$10)*((COLUMN()-3)=$D$6:$D$10)*($H$6:$H$10)) -> 0 | ... AA22: =SUMPRODUCT(($C$6:$C$10)*((COLUMN()-3)=$D$6:$D$10)*($H$6:$H$10)) -> 0
B23: Expansion ramp opex | C23: =SUMPRODUCT(($C$6:$C$10)*((COLUMN()-3)>=$D$6:$D$10)*((COLUMN()-3)<$D$6:$D$10+$J$6:$J$10)*($I$6:$I$10)) -> 0 | D23: =SUMPRODUCT(($C$6:$C$10)*((COLUMN()-3)>=$D$6:$D$10)*((COLUMN()-3)<$D$6:$D$10+$J$6:$J$10)*($I$6:$I$10)) -> 0 | E23: =SUMPRODUCT(($C$6:$C$10)*((COLUMN()-3)>=$D$6:$D$10)*((COLUMN()-3)<$D$6:$D$10+$J$6:$J$10)*($I$6:$I$10)) -> 0 | F23: =SUMPRODUCT(($C$6:$C$10)*((COLUMN()-3)>=$D$6:$D$10)*((COLUMN()-3)<$D$6:$D$10+$J$6:$J$10)*($I$6:$I$10)) -> 0 | G23: =SUMPRODUCT(($C$6:$C$10)*((COLUMN()-3)>=$D$6:$D$10)*((COLUMN()-3)<$D$6:$D$10+$J$6:$J$10)*($I$6:$I$10)) -> 0 | H23: =SUMPRODUCT(($C$6:$C$10)*((COLUMN()-3)>=$D$6:$D$10)*((COLUMN()-3)<$D$6:$D$10+$J$6:$J$10)*($I$6:$I$10)) -> 0 | I23: =SUMPRODUCT(($C$6:$C$10)*((COLUMN()-3)>=$D$6:$D$10)*((COLUMN()-3)<$D$6:$D$10+$J$6:$J$10)*($I$6:$I$10)) -> 0 | J23: =SUMPRODUCT(($C$6:$C$10)*((COLUMN()-3)>=$D$6:$D$10)*((COLUMN()-3)<$D$6:$D$10+$J$6:$J$10)*($I$6:$I$10)) -> 0 | ... AA23: =SUMPRODUCT(($C$6:$C$10)*((COLUMN()-3)>=$D$6:$D$10)*((COLUMN()-3)<$D$6:$D$10+$J$6:$J$10)*($I$6:$I$10)) -> 0
B25: Existing-market Mo-0 revenue ties to the consolidated P&L (May total revenue). All figures illustrative.

Sheet Labor Model
B2: Hybrid-Care Clinical Labor Model ($000s)
B3: Visits split across in-person and telehealth drive provider FTEs and cost. This builds gross profit for the Financing tab.
B5: Care model & productivity drivers
B6: Net revenue per visit ($) | C6: 298
B7: Telehealth share of visits | C7: 0.45
B8: In-person share of visits | C8: =1-C7 -> 0.55
B9: Working days / month | C9: 21
B10: Clinical utilization | C10: 0.8
B11: Non-labor COGS (% of revenue) | C11: 0.183
B13: Clinical role | C13: Modality | D13: Sizing basis | E13: Driver | F13: Loaded $/yr | G13: FTE (Mo-0) | H13: Cost/mo (Mo-0)
B14: In-person clinician | C14: In-person | D14: Visits / day | E14: 11 | F14: 260000 | G14: =C25 -> 54.130713 | H14: =C25*F14/12/1000 -> 1172.8321
B15: Telehealth clinician | C15: Telehealth | D15: Visits / day | E15: 16 | F15: 230000 | G15: =C26 -> 30.448526 | H15: =C26*F15/12/1000 -> 583.59675
B16: RN / nursing support | C16: Both | D16: Ratio / clinician | E16: 0.5 | F16: 120000 | G16: =C27 -> 42.289619 | H16: =C27*F16/12/1000 -> 422.89619
B17: Behavioral-health tech / MA | C17: In-person | D17: Ratio / IP clinician | E17: 0.8 | F17: 70000 | G17: =C28 -> 43.30457 | H17: =C28*F17/12/1000 -> 252.60999
B18: Care coordinator | C18: Both | D18: Ratio / clinician | E18: 0.3 | F18: 75000 | G18: =C29 -> 25.373772 | H18: =C29*F18/12/1000 -> 158.58607
B19: Clinical supervisor / lead | C19: Both | D19: Ratio / clinician | E19: 0.12 | F19: 160000 | G19: =C30 -> 10.149509 | H19: =C30*F19/12/1000 -> 135.32678
B20: Total / Mo-0 | G20: =C31 -> 205.69671 | H20: =C32 -> 2725.8479
B21: Monthly build | C21: M0 | D21: M1 | E21: M2 | F21: M3 | G21: M4 | H21: M5 | I21: M6 | J21: M7 | K21: M8 | L21: M9 | M21: M10 | N21: M11 | O21: M12 | P21: M13 | Q21: M14 | R21: M15 | S21: M16 | T21: M17 | U21: M18 | V21: M19 | W21: M20 | X21: M21 | Y21: M22 | Z21: M23 | AA21: M24
B22: Total visits | C22: =Regions!C19*1000/$C$6 -> 18187.919 | D22: =Regions!D19*1000/$C$6 -> 18543.087 | E22: =Regions!E19*1000/$C$6 -> 18905.234 | F22: =Regions!F19*1000/$C$6 -> 19274.497 | G22: =Regions!G19*1000/$C$6 -> 19651.018 | H22: =Regions!H19*1000/$C$6 -> 20034.94 | I22: =Regions!I19*1000/$C$6 -> 20426.409 | J22: =Regions!J19*1000/$C$6 -> 20825.576 | ... AA22: =Regions!AA19*1000/$C$6 -> 28949.069
B23: Telehealth visits | C23: =C22*$C$7 -> 8184.5638 | D23: =D22*$C$7 -> 8344.3893 | E23: =E22*$C$7 -> 8507.3552 | F23: =F22*$C$7 -> 8673.5237 | G23: =G22*$C$7 -> 8842.9581 | H23: =H22*$C$7 -> 9015.723 | I23: =I22*$C$7 -> 9191.8843 | J23: =J22*$C$7 -> 9371.5091 | ... AA23: =AA22*$C$7 -> 13027.081
B24: In-person visits | C24: =C22*$C$8 -> 10003.356 | D24: =D22*$C$8 -> 10198.698 | E24: =E22*$C$8 -> 10397.879 | F24: =F22*$C$8 -> 10600.973 | G24: =G22*$C$8 -> 10808.06 | H24: =H22*$C$8 -> 11019.217 | I24: =I22*$C$8 -> 11234.525 | J24: =J22*$C$8 -> 11454.067 | ... AA24: =AA22*$C$8 -> 15921.988
B25: In-person clinician FTE | C25: =C24/($C$9*$C$10*$E$14) -> 54.130713 | D25: =D24/($C$9*$C$10*$E$14) -> 55.18776 | E25: =E24/($C$9*$C$10*$E$14) -> 56.265577 | F25: =F24/($C$9*$C$10*$E$14) -> 57.364575 | G25: =G24/($C$9*$C$10*$E$14) -> 58.485173 | H25: =H24/($C$9*$C$10*$E$14) -> 59.627798 | I25: =I24/($C$9*$C$10*$E$14) -> 60.792885 | J25: =J24/($C$9*$C$10*$E$14) -> 61.98088 | ... AA25: =AA24/($C$9*$C$10*$E$14) -> 86.157943
B26: Telehealth clinician FTE | C26: =C23/($C$9*$C$10*$E$15) -> 30.448526 | D26: =D23/($C$9*$C$10*$E$15) -> 31.043115 | E26: =E23/($C$9*$C$10*$E$15) -> 31.649387 | F26: =F23/($C$9*$C$10*$E$15) -> 32.267573 | G26: =G23/($C$9*$C$10*$E$15) -> 32.89791 | H26: =H23/($C$9*$C$10*$E$15) -> 33.540636 | I26: =I23/($C$9*$C$10*$E$15) -> 34.195998 | J26: =J23/($C$9*$C$10*$E$15) -> 34.864245 | ... AA26: =AA23/($C$9*$C$10*$E$15) -> 48.463843
B27: RN / nursing FTE | C27: =(C25+C26)*$E$16 -> 42.289619 | D27: =(D25+D26)*$E$16 -> 43.115437 | E27: =(E25+E26)*$E$16 -> 43.957482 | F27: =(F25+F26)*$E$16 -> 44.816074 | G27: =(G25+G26)*$E$16 -> 45.691541 | H27: =(H25+H26)*$E$16 -> 46.584217 | I27: =(I25+I26)*$E$16 -> 47.494442 | J27: =(J25+J26)*$E$16 -> 48.422563 | ... AA27: =(AA25+AA26)*$E$16 -> 67.310893
B28: BH tech / MA FTE | C28: =C25*$E$17 -> 43.30457 | D28: =D25*$E$17 -> 44.150208 | E28: =E25*$E$17 -> 45.012461 | F28: =F25*$E$17 -> 45.89166 | G28: =G25*$E$17 -> 46.788138 | H28: =H25*$E$17 -> 47.702238 | I28: =I25*$E$17 -> 48.634308 | J28: =J25*$E$17 -> 49.584704 | ... AA28: =AA25*$E$17 -> 68.926354
B29: Care coordinator FTE | C29: =(C25+C26)*$E$18 -> 25.373772 | D29: =(D25+D26)*$E$18 -> 25.869262 | E29: =(E25+E26)*$E$18 -> 26.374489 | F29: =(F25+F26)*$E$18 -> 26.889645 | G29: =(G25+G26)*$E$18 -> 27.414925 | H29: =(H25+H26)*$E$18 -> 27.95053 | I29: =(I25+I26)*$E$18 -> 28.496665 | J29: =(J25+J26)*$E$18 -> 29.053538 | ... AA29: =(AA25+AA26)*$E$18 -> 40.386536
B30: Clinical supervisor FTE | C30: =(C25+C26)*$E$19 -> 10.149509 | D30: =(D25+D26)*$E$19 -> 10.347705 | E30: =(E25+E26)*$E$19 -> 10.549796 | F30: =(F25+F26)*$E$19 -> 10.755858 | G30: =(G25+G26)*$E$19 -> 10.96597 | H30: =(H25+H26)*$E$19 -> 11.180212 | I30: =(I25+I26)*$E$19 -> 11.398666 | J30: =(J25+J26)*$E$19 -> 11.621415 | ... AA30: =(AA25+AA26)*$E$19 -> 16.154614
B31: Total clinical FTE | C31: =SUM(C25:C30) -> 205.69671 | D31: =SUM(D25:D30) -> 209.71349 | E31: =SUM(E25:E30) -> 213.80919 | F31: =SUM(F25:F30) -> 217.98538 | G31: =SUM(G25:G30) -> 222.24366 | H31: =SUM(H25:H30) -> 226.58563 | I31: =SUM(I25:I30) -> 231.01296 | J31: =SUM(J25:J30) -> 235.52734 | ... AA31: =SUM(AA25:AA30) -> 327.40018
B32: Clinical labor cost | C32: =(C25*$F$14+C26*$F$15+C27*$F$16+C28*$F$17+C29*$F$18+C30*$F$19)/12/1000 -> 2725.8479 | D32: =(D25*$F$14+D26*$F$15+D27*$F$16+D28*$F$17+D29*$F$18+D30*$F$19)/12/1000 -> 2779.0774 | E32: =(E25*$F$14+E26*$F$15+E27*$F$16+E28*$F$17+E29*$F$18+E30*$F$19)/12/1000 -> 2833.3528 | F32: =(F25*$F$14+F26*$F$15+F27*$F$16+F28*$F$17+F29*$F$18+F30*$F$19)/12/1000 -> 2888.6948 | G32: =(G25*$F$14+G26*$F$15+G27*$F$16+G28*$F$17+G29*$F$18+G30*$F$19)/12/1000 -> 2945.1244 | H32: =(H25*$F$14+H26*$F$15+H27*$F$16+H28*$F$17+H29*$F$18+H30*$F$19)/12/1000 -> 3002.6633 | I32: =(I25*$F$14+I26*$F$15+I27*$F$16+I28*$F$17+I29*$F$18+I30*$F$19)/12/1000 -> 3061.3334 | J32: =(J25*$F$14+J26*$F$15+J27*$F$16+J28*$F$17+J29*$F$18+J30*$F$19)/12/1000 -> 3121.157 | ... AA32: =(AA25*$F$14+AA26*$F$15+AA27*$F$16+AA28*$F$17+AA29*$F$18+AA30*$F$19)/12/1000 -> 4338.6358
B33: Non-labor COGS | C33: =$C$11*Regions!C19 -> 991.86 | D33: =$C$11*Regions!D19 -> 1011.2287 | E33: =$C$11*Regions!E19 -> 1030.978 | F33: =$C$11*Regions!F19 -> 1051.1154 | G33: =$C$11*Regions!G19 -> 1071.6486 | H33: =$C$11*Regions!H19 -> 1092.5854 | I33: =$C$11*Regions!I19 -> 1113.9338 | J33: =$C$11*Regions!J19 -> 1135.7019 | ... AA33: =$C$11*Regions!AA19 -> 1578.7085
B34: Total COGS | C34: =C32+C33 -> 3717.7079 | D34: =D32+D33 -> 3790.3061 | E34: =E32+E33 -> 3864.3308 | F34: =F32+F33 -> 3939.8102 | G34: =G32+G33 -> 4016.7731 | H34: =H32+H33 -> 4095.2488 | I34: =I32+I33 -> 4175.2672 | J34: =J32+J33 -> 4256.8589 | ... AA34: =AA32+AA33 -> 5917.3443
B35: Gross profit | C35: =Regions!C19-C34 -> 1702.2921 | D35: =Regions!D19-D34 -> 1735.5339 | E35: =Regions!E19-E34 -> 1769.4289 | F35: =Regions!F19-F34 -> 1803.99 | G35: =Regions!G19-G34 -> 1839.2303 | H35: =Regions!H19-H34 -> 1875.1634 | I35: =Regions!I19-I34 -> 1911.8028 | J35: =Regions!J19-J34 -> 1949.1626 | ... AA35: =Regions!AA19-AA34 -> 2709.4782
B36: Gross margin % | C36: =IF(Regions!C19=0,0,C35/Regions!C19) -> 0.31407603 | D36: =IF(Regions!D19=0,0,D35/Regions!D19) -> 0.31407603 | E36: =IF(Regions!E19=0,0,E35/Regions!E19) -> 0.31407603 | F36: =IF(Regions!F19=0,0,F35/Regions!F19) -> 0.31407603 | G36: =IF(Regions!G19=0,0,G35/Regions!G19) -> 0.31407603 | H36: =IF(Regions!H19=0,0,H35/Regions!H19) -> 0.31407603 | I36: =IF(Regions!I19=0,0,I35/Regions!I19) -> 0.31407603 | J36: =IF(Regions!J19=0,0,J35/Regions!J19) -> 0.31407603 | ... AA36: =IF(Regions!AA19=0,0,AA35/Regions!AA19) -> 0.31407603
B38: Mo-0 read-out
B39: ="Clinical labor: $"&TEXT(C32,"#,##0")&"K/mo · Total clinical FTE: "&TEXT(C31,"#,##0")&" · Blended gross margin: "&TEXT(C36,"0.0%") -> Clinical labor: $2,726K/mo · Total clinical FTE: 206 · Blended gross margin: 31.4%
B40: Telehealth mix is the key lever: raising the telehealth share lifts throughput and lowers labor cost per visit, expanding margin. Mo-0 clinical labor approximately reconciles to the consolidated P&L. Illustrative.

Sheet Financing & Runway
B2: Financing & Runway — Series B Timing ($000s)
B3: Revenue links from Regions; gross profit is built bottom-up in the Labor Model. Toggle financing to see runway extend.
B5: Operating assumptions | E5: Financing levers
B6: Starting cash | C6: 3500 | E6: Equity raise — include? (1/0) | G6: 0
B7: Corporate opex (Mo-0) | C7: 1380 | E7: Equity amount | G7: 12000
B8: Corporate opex growth (MoM) | C8: 0.015 | E8: Equity close month | G8: 9
B9: Capex / month (base) | C9: 150 | E9: Venture debt — include? (1/0) | G9: 0
B10: Working-capital drag / mo | C10: 90 | E10: Debt amount drawn | G10: 5000
B11: Minimum cash threshold | C11: 1500 | E11: Debt draw month | G11: 6
B12: Fundraise lead time (months) | C12: 6 | E12: Debt annual interest rate | G12: 0.12
B15: Month | C15: M1 | D15: M2 | E15: M3 | F15: M4 | G15: M5 | H15: M6 | I15: M7 | J15: M8 | K15: M9 | L15: M10 | M15: M11 | N15: M12 | O15: M13 | P15: M14 | Q15: M15 | R15: M16 | S15: M17 | T15: M18 | U15: M19 | V15: M20 | W15: M21 | X15: M22 | Y15: M23 | Z15: M24
B16: Revenue (from Regions) | C16: =Regions!D19 -> 5525.84 | D16: =Regions!E19 -> 5633.7597 | E16: =Regions!F19 -> 5743.8002 | F16: =Regions!G19 -> 5856.0034 | G16: =Regions!H19 -> 5970.4121 | H16: =Regions!I19 -> 6087.07 | I16: =Regions!J19 -> 6206.0216 | J16: =Regions!K19 -> 6327.3121 | ... Z16: =Regions!AA19 -> 8626.8225
B17: Gross profit | C17: ='Labor Model'!D35 -> 1735.5339 | D17: ='Labor Model'!E35 -> 1769.4289 | E17: ='Labor Model'!F35 -> 1803.99 | F17: ='Labor Model'!G35 -> 1839.2303 | G17: ='Labor Model'!H35 -> 1875.1634 | H17: ='Labor Model'!I35 -> 1911.8028 | I17: ='Labor Model'!J35 -> 1949.1626 | J17: ='Labor Model'!K35 -> 1987.2571 | ... Z17: ='Labor Model'!AA35 -> 2709.4782
B18: Corporate opex | C18: =$C$7*(1+$C$8)^1 -> 1400.7 | D18: =$C$7*(1+$C$8)^2 -> 1421.7105 | E18: =$C$7*(1+$C$8)^3 -> 1443.0362 | F18: =$C$7*(1+$C$8)^4 -> 1464.6817 | G18: =$C$7*(1+$C$8)^5 -> 1486.6519 | H18: =$C$7*(1+$C$8)^6 -> 1508.9517 | I18: =$C$7*(1+$C$8)^7 -> 1531.586 | J18: =$C$7*(1+$C$8)^8 -> 1554.5598 | K18: =$C$7*(1+$C$8)^9 -> 1577.8782 | L18: =$C$7*(1+$C$8)^10 -> 1601.5463 | M18: =$C$7*(1+$C$8)^11 -> 1625.5695 | N18: =$C$7*(1+$C$8)^12 -> 1649.9531 | O18: =$C$7*(1+$C$8)^13 -> 1674.7024 | P18: =$C$7*(1+$C$8)^14 -> 1699.8229 | Q18: =$C$7*(1+$C$8)^15 -> 1725.3203 | R18: =$C$7*(1+$C$8)^16 -> 1751.2001 | S18: =$C$7*(1+$C$8)^17 -> 1777.4681 | T18: =$C$7*(1+$C$8)^18 -> 1804.1301 | U18: =$C$7*(1+$C$8)^19 -> 1831.192 | V18: =$C$7*(1+$C$8)^20 -> 1858.6599 | W18: =$C$7*(1+$C$8)^21 -> 1886.5398 | X18: =$C$7*(1+$C$8)^22 -> 1914.8379 | Y18: =$C$7*(1+$C$8)^23 -> 1943.5605 | Z18: =$C$7*(1+$C$8)^24 -> 1972.7139
B19: Expansion ramp opex | C19: =Regions!D23 -> 0 | D19: =Regions!E23 -> 0 | E19: =Regions!F23 -> 0 | F19: =Regions!G23 -> 0 | G19: =Regions!H23 -> 0 | H19: =Regions!I23 -> 0 | I19: =Regions!J23 -> 0 | J19: =Regions!K23 -> 0 | ... Z19: =Regions!AA23 -> 0
B20: Total opex | C20: =C18+C19 -> 1400.7 | D20: =D18+D19 -> 1421.7105 | E20: =E18+E19 -> 1443.0362 | F20: =F18+F19 -> 1464.6817 | G20: =G18+G19 -> 1486.6519 | H20: =H18+H19 -> 1508.9517 | I20: =I18+I19 -> 1531.586 | J20: =J18+J19 -> 1554.5598 | ... Z20: =Z18+Z19 -> 1972.7139
B21: EBITDA | C21: =C17-C20 -> 334.83391 | D21: =D17-D20 -> 347.7184 | E21: =E17-E20 -> 360.95382 | F21: =F17-F20 -> 374.54862 | G21: =G17-G20 -> 388.51144 | H21: =H17-H20 -> 402.85111 | I21: =I17-I20 -> 417.57666 | J21: =J17-J20 -> 432.69733 | ... Z21: =Z17-Z20 -> 736.76431
B22: Base capex | C22: =$C$9 -> 150 | D22: =$C$9 -> 150 | E22: =$C$9 -> 150 | F22: =$C$9 -> 150 | G22: =$C$9 -> 150 | H22: =$C$9 -> 150 | I22: =$C$9 -> 150 | J22: =$C$9 -> 150 | ... Z22: =$C$9 -> 150
B23: Expansion launch capex | C23: =Regions!D22 -> 0 | D23: =Regions!E22 -> 0 | E23: =Regions!F22 -> 0 | F23: =Regions!G22 -> 0 | G23: =Regions!H22 -> 0 | H23: =Regions!I22 -> 0 | I23: =Regions!J22 -> 0 | J23: =Regions!K22 -> 0 | ... Z23: =Regions!AA22 -> 0
B24: Working-capital drag | C24: =$C$10 -> 90 | D24: =$C$10 -> 90 | E24: =$C$10 -> 90 | F24: =$C$10 -> 90 | G24: =$C$10 -> 90 | H24: =$C$10 -> 90 | I24: =$C$10 -> 90 | J24: =$C$10 -> 90 | ... Z24: =$C$10 -> 90
B25: Interest expense | C25: =IF(AND($G$9=1,1>=$G$11),$G$10*$G$12/12,0) -> 0 | D25: =IF(AND($G$9=1,2>=$G$11),$G$10*$G$12/12,0) -> 0 | E25: =IF(AND($G$9=1,3>=$G$11),$G$10*$G$12/12,0) -> 0 | F25: =IF(AND($G$9=1,4>=$G$11),$G$10*$G$12/12,0) -> 0 | G25: =IF(AND($G$9=1,5>=$G$11),$G$10*$G$12/12,0) -> 0 | H25: =IF(AND($G$9=1,6>=$G$11),$G$10*$G$12/12,0) -> 0 | I25: =IF(AND($G$9=1,7>=$G$11),$G$10*$G$12/12,0) -> 0 | J25: =IF(AND($G$9=1,8>=$G$11),$G$10*$G$12/12,0) -> 0 | K25: =IF(AND($G$9=1,9>=$G$11),$G$10*$G$12/12,0) -> 0 | L25: =IF(AND($G$9=1,10>=$G$11),$G$10*$G$12/12,0) -> 0 | M25: =IF(AND($G$9=1,11>=$G$11),$G$10*$G$12/12,0) -> 0 | N25: =IF(AND($G$9=1,12>=$G$11),$G$10*$G$12/12,0) -> 0 | O25: =IF(AND($G$9=1,13>=$G$11),$G$10*$G$12/12,0) -> 0 | P25: =IF(AND($G$9=1,14>=$G$11),$G$10*$G$12/12,0) -> 0 | Q25: =IF(AND($G$9=1,15>=$G$11),$G$10*$G$12/12,0) -> 0 | R25: =IF(AND($G$9=1,16>=$G$11),$G$10*$G$12/12,0) -> 0 | S25: =IF(AND($G$9=1,17>=$G$11),$G$10*$G$12/12,0) -> 0 | T25: =IF(AND($G$9=1,18>=$G$11),$G$10*$G$12/12,0) -> 0 | U25: =IF(AND($G$9=1,19>=$G$11),$G$10*$G$12/12,0) -> 0 | V25: =IF(AND($G$9=1,20>=$G$11),$G$10*$G$12/12,0) -> 0 | W25: =IF(AND($G$9=1,21>=$G$11),$G$10*$G$12/12,0) -> 0 | X25: =IF(AND($G$9=1,22>=$G$11),$G$10*$G$12/12,0) -> 0 | Y25: =IF(AND($G$9=1,23>=$G$11),$G$10*$G$12/12,0) -> 0 | Z25: =IF(AND($G$9=1,24>=$G$11),$G$10*$G$12/12,0) -> 0
B26: Operating cash flow | C26: =C21-C22-C23-C24 -> 94.833914 | D26: =D21-D22-D23-D24 -> 107.7184 | E26: =E21-E22-E23-E24 -> 120.95382 | F26: =F21-F22-F23-F24 -> 134.54862 | G26: =G21-G22-G23-G24 -> 148.51144 | H26: =H21-H22-H23-H24 -> 162.85111 | I26: =I21-I22-I23-I24 -> 177.57666 | J26: =J21-J22-J23-J24 -> 192.69733 | ... Z26: =Z21-Z22-Z23-Z24 -> 496.76431
B27: Cash before financing | C27: =$C$6+C26 -> 3594.8339 | D27: =C27+D26 -> 3702.5523 | E27: =D27+E26 -> 3823.5061 | F27: =E27+F26 -> 3958.0548 | G27: =F27+G26 -> 4106.5662 | H27: =G27+H26 -> 4269.4173 | I27: =H27+I26 -> 4446.994 | J27: =I27+J26 -> 4639.6913 | K27: =J27+K26 -> 4847.9138 | ... Z27: =Y27+Z26 -> 10140.89
B29: Equity inflow | C29: =IF(AND($G$6=1,1=$G$8),$G$7,0) -> 0 | D29: =IF(AND($G$6=1,2=$G$8),$G$7,0) -> 0 | E29: =IF(AND($G$6=1,3=$G$8),$G$7,0) -> 0 | F29: =IF(AND($G$6=1,4=$G$8),$G$7,0) -> 0 | G29: =IF(AND($G$6=1,5=$G$8),$G$7,0) -> 0 | H29: =IF(AND($G$6=1,6=$G$8),$G$7,0) -> 0 | I29: =IF(AND($G$6=1,7=$G$8),$G$7,0) -> 0 | J29: =IF(AND($G$6=1,8=$G$8),$G$7,0) -> 0 | K29: =IF(AND($G$6=1,9=$G$8),$G$7,0) -> 0 | L29: =IF(AND($G$6=1,10=$G$8),$G$7,0) -> 0 | M29: =IF(AND($G$6=1,11=$G$8),$G$7,0) -> 0 | N29: =IF(AND($G$6=1,12=$G$8),$G$7,0) -> 0 | O29: =IF(AND($G$6=1,13=$G$8),$G$7,0) -> 0 | P29: =IF(AND($G$6=1,14=$G$8),$G$7,0) -> 0 | Q29: =IF(AND($G$6=1,15=$G$8),$G$7,0) -> 0 | R29: =IF(AND($G$6=1,16=$G$8),$G$7,0) -> 0 | S29: =IF(AND($G$6=1,17=$G$8),$G$7,0) -> 0 | T29: =IF(AND($G$6=1,18=$G$8),$G$7,0) -> 0 | U29: =IF(AND($G$6=1,19=$G$8),$G$7,0) -> 0 | V29: =IF(AND($G$6=1,20=$G$8),$G$7,0) -> 0 | W29: =IF(AND($G$6=1,21=$G$8),$G$7,0) -> 0 | X29: =IF(AND($G$6=1,22=$G$8),$G$7,0) -> 0 | Y29: =IF(AND($G$6=1,23=$G$8),$G$7,0) -> 0 | Z29: =IF(AND($G$6=1,24=$G$8),$G$7,0) -> 0
B30: Debt inflow | C30: =IF(AND($G$9=1,1=$G$11),$G$10,0) -> 0 | D30: =IF(AND($G$9=1,2=$G$11),$G$10,0) -> 0 | E30: =IF(AND($G$9=1,3=$G$11),$G$10,0) -> 0 | F30: =IF(AND($G$9=1,4=$G$11),$G$10,0) -> 0 | G30: =IF(AND($G$9=1,5=$G$11),$G$10,0) -> 0 | H30: =IF(AND($G$9=1,6=$G$11),$G$10,0) -> 0 | I30: =IF(AND($G$9=1,7=$G$11),$G$10,0) -> 0 | J30: =IF(AND($G$9=1,8=$G$11),$G$10,0) -> 0 | K30: =IF(AND($G$9=1,9=$G$11),$G$10,0) -> 0 | L30: =IF(AND($G$9=1,10=$G$11),$G$10,0) -> 0 | M30: =IF(AND($G$9=1,11=$G$11),$G$10,0) -> 0 | N30: =IF(AND($G$9=1,12=$G$11),$G$10,0) -> 0 | O30: =IF(AND($G$9=1,13=$G$11),$G$10,0) -> 0 | P30: =IF(AND($G$9=1,14=$G$11),$G$10,0) -> 0 | Q30: =IF(AND($G$9=1,15=$G$11),$G$10,0) -> 0 | R30: =IF(AND($G$9=1,16=$G$11),$G$10,0) -> 0 | S30: =IF(AND($G$9=1,17=$G$11),$G$10,0) -> 0 | T30: =IF(AND($G$9=1,18=$G$11),$G$10,0) -> 0 | U30: =IF(AND($G$9=1,19=$G$11),$G$10,0) -> 0 | V30: =IF(AND($G$9=1,20=$G$11),$G$10,0) -> 0 | W30: =IF(AND($G$9=1,21=$G$11),$G$10,0) -> 0 | X30: =IF(AND($G$9=1,22=$G$11),$G$10,0) -> 0 | Y30: =IF(AND($G$9=1,23=$G$11),$G$10,0) -> 0 | Z30: =IF(AND($G$9=1,24=$G$11),$G$10,0) -> 0
B31: Net cash flow (all-in) | C31: =C26-C25+C29+C30 -> 94.833914 | D31: =D26-D25+D29+D30 -> 107.7184 | E31: =E26-E25+E29+E30 -> 120.95382 | F31: =F26-F25+F29+F30 -> 134.54862 | G31: =G26-G25+G29+G30 -> 148.51144 | H31: =H26-H25+H29+H30 -> 162.85111 | I31: =I26-I25+I29+I30 -> 177.57666 | J31: =J26-J25+J29+J30 -> 192.69733 | ... Z31: =Z26-Z25+Z29+Z30 -> 496.76431
B32: Ending cash | C32: =$C$6+C31 -> 3594.8339 | D32: =C32+D31 -> 3702.5523 | E32: =D32+E31 -> 3823.5061 | F32: =E32+F31 -> 3958.0548 | G32: =F32+G31 -> 4106.5662 | H32: =G32+H31 -> 4269.4173 | I32: =H32+I31 -> 4446.994 | J32: =I32+J31 -> 4639.6913 | K32: =J32+K31 -> 4847.9138 | ... Z32: =Y32+Z31 -> 10140.89
B33: Below minimum? (op) | C33: =IF(C27<$C$11,1,0) -> 0 | D33: =IF(D27<$C$11,1,0) -> 0 | E33: =IF(E27<$C$11,1,0) -> 0 | F33: =IF(F27<$C$11,1,0) -> 0 | G33: =IF(G27<$C$11,1,0) -> 0 | H33: =IF(H27<$C$11,1,0) -> 0 | I33: =IF(I27<$C$11,1,0) -> 0 | J33: =IF(J27<$C$11,1,0) -> 0 | ... Z33: =IF(Z27<$C$11,1,0) -> 0
B34: Series B — Timing & Sizing
B35: Cash-out month — expansion, before raise | C35: =IFERROR(MATCH(1,C33:Z33,0),"Beyond 24 mo") -> Beyond 24 mo
B36: Operating runway (months) | C36: =IF(ISNUMBER(C35),C35-1,"24+") -> 24+
B37: Recommended Series B close-by month | C37: =IF(ISNUMBER(C35),MAX(0,C35-$C$12),"—") -> —
B38: Capital needed to hold the minimum | C38: =MAX(0,$C$11-MIN(C27:Z27)) -> 0
B39: Min cash before financing | C39: =MIN(C27:Z27) -> 3594.8339
B40: Ending cash at M24 (current toggles) | C40: =Z32 -> 10140.89
B41: Min cash at any point (current toggles) | C41: =MIN(C32:Z32) -> 3594.8339
B43: Read-out
B44: ="With current toggles: "&IF(ISNUMBER(C35),"cash falls below the $"&TEXT($C$11,"#,##0")&"K floor in month "&C35&" — target a Series B close by month "&C37&" and raise at least $"&TEXT(ROUNDUP(C38/1000,1),"0.0")&"M.","operations stay above the floor for 24+ months. Toggle the expansion regions ON in the Regions tab to model the growth case that requires a Series B.") -> With current toggles: operations stay above the floor for 24+ months. Toggle the expansion regions ON in the Regions tab to model the growth case that requires a Series B.
B46: How to use
B47: 1. Turn on expansion in Regions (set Southeast / Northeast Active = 1) to model the growth plan.
...

Sheet Variance Narrative
B2: Variance Narrative — May 2026
B3: Auto-drafted from the P&L tab with Claude, then reviewed and approved by Finance. Figures in $000s.
B5: EXECUTIVE SUMMARY
B6: May EBITDA of $290K landed $380K (57%) below the $670K plan. The miss was driven primarily by gross-margin compression rather than a top-line shortfall: gross margin came in at 30.8% versus a planned 35.5%. Revenue of $5,420K was $180K (3.2%) light to budget, while total direct costs ran $140K over plan.
B8: REVENUE
B9: Patient service revenue of $3,980K was $220K (5.2%) below plan on a ~400-visit volume shortfall (18,200 actual vs. 18,600 budgeted). This was partially offset by capitation & value-based revenue of $1,240K, $60K ahead of plan, as two recently signed value-based contracts ramped faster than expected. Net revenue per visit held roughly in line with plan, so the gap is a volume story, not a rate story.
B11: DIRECT COSTS / GROSS MARGIN
B12: Clinical labor of $2,760K exceeded budget by $110K (4.2%) and is the single largest driver of the EBITDA miss. Premium agency staffing was used to cover open clinical roles, raising the effective cost per visit. Medical supplies ($520K) and clinical facilities ($470K) were modestly over plan. With labor at roughly 74% of direct cost, staffing model decisions are the highest-leverage margin lever this quarter.
B14: OPERATING EXPENSES
B15: Total operating expense of $1,380K was $60K over plan. Sales & marketing ($410K) accounted for $30K of that as a demand-generation campaign was pulled forward from June; G&A and technology were each marginally over. Below-gross-margin spend was not a primary driver of the miss.
B17: YEAR-TO-DATE
B18: Through May, EBITDA of $1,870K trails the $3,370K plan by $1,500K (6.9% margin vs. 12.1% planned). The YTD story mirrors the month: revenue tracking ~3% under plan on volume, and direct labor running ahead of budget.
... B21: 1) Convert agency clinical hours to permanent hires to structurally lower cost per visit. 2) Diagnose the patient-volume shortfall (referral mix, scheduling capacity, or seasonality) before the Q3 reforecast. 3) Protect and accelerate the value-based revenue ramp, which is the clearest offset in the plan. 4) Re-baseline the labor assumption in the reforecast if agency reliance persists into June.
