Workbook

Sheet Cover
B2: Value-Based Primary Care — Capitation Financial Model
B3: Greenbrook-scale · ~$60M revenue · 4 clinics · ~4,500 members · 4 MA / Medicare payors
B5: PURPOSE
B6: Demonstrates how a senior-focused primary care clinic earns and bears risk across four
B7: different value-based contract structures simultaneously, and how the two core profit
B8: levers — RISK SCORE (RAF) capture and TOTAL COST OF CARE (TCOC) management — drive
B9: the medical margin and the cohort J-curve as a panel matures.
B11: THE FOUR CONTRACTS
B12: A · Full / Global Capitation
B13: 100% TCOC risk. Revenue = % of risk-adjusted premium. Provider pays claims; keeps surplus, bears deficit. Stop-loss protection.
B14: B · Two-Sided Shared Risk
B15: Care-management PMPM + 50/50 share of savings/losses vs a TCOC target. Plan pays claims; provider settles the shared portion.
... B21: TABS
B22: Assumptions | C22: All inputs & levers (blue). Edit here to flex scenarios.
B23: A·FullCap / B·TwoSided / C·Upside / D·REACH | C23: Per-contract monthly economics (Year 1).
B24: P&L (Monthly) | C24: Consolidated Year-1 monthly P&L to EBITDA.
B25: Cash Flow | C25: Full-cap cash dynamics: cap received vs claims paid in arrears + IBNR build.
B26: 3-Yr & Cohorts | C26: Annual summary + cohort J-curve showing RAF & TCOC levers maturing.
B27: KPIs | C27: Dashboard: MLR, medical margin PMPM, utilization by contract.
B30: COLOR KEY
B31: Blue = input/assumption | C31: Black = formula | D31: Green = cross-sheet link
B33: Illustrative model. Assumptions are synthetic and directional, not Greenbrook actuals.

Sheet Assumptions
A1: ASSUMPTIONS & LEVERS
A3: GLOBAL
A4: Model start year | B4: 2026
A5: Annual medical cost trend | B5: 0.05
A6: Annual premium / benchmark trend | B6: 0.035
A7: IBNR accrual (% of monthly medical cost) | B7: 0.12
A8: Claims payment lag (months) | B8: 2
A9: New-clinic TCOC factor — Month 1 | B9: 1.06
A10: New-clinic TCOC factor — Month 12 | B10: 1
A11: Inpatient admits / 1,000 (mature) | B11: 185
A13: CLINIC OPERATING COSTS
A14: Fixed clinic opex / month ($) | B14: 380000
A15: Care management — variable PMPM ($) | B15: 18
A16: G&A / corporate / month ($) | B16: 120000
A18: TCOC BUCKET MIX (% of total medical spend)
A19: Inpatient | B19: 0.3
A20: Outpatient / ED | B20: 0.16
A21: Specialist professional | B21: 0.18
A22: Primary care (internal) | B22: 0.08
A23: Post-acute / SNF | B23: 0.1
A24: Pharmacy (Part D) | B24: 0.12
A25: Ancillary (lab / imaging / DME) | B25: 0.04
A26: Other | B26: 0.02
A27: Total | B27: =SUM(B19:B26) -> 1
A29: CONTRACT TERMS
A30: Metric | B30: A · Full Cap | C30: B · Two-Sided | D30: C · Upside-Only | E30: D · ACO REACH
A31: Population / payor | B31: MA — Payor A | C31: MA — Payor B | D31: MA — Payor C | E31: Traditional Medicare
A32: Risk model | B32: Full global cap | C32: Two-sided shared | D32: Upside-only | E32: REACH Professional
A33: Full-cap flag (1=yes) | B33: 1 | C33: 0 | D33: 0 | E33: 0
A34: Starting members (Month 1) | B34: 3600 | C34: 450 | D34: 250 | E34: 200
A35: Monthly member growth | B35: 0.01 | C35: 0.01 | D35: 0.01 | E35: 0.015
A36: Mature RAF (risk score) | B36: 1.12 | C36: 1.05 | D36: 1 | E36: 1.05
A37: Premium / benchmark PMPM ($) | B37: 1450 | C37: 1350 | D37: 1250 | E37: 1150
A38: Provider cap % of premium | B38: 0.9 | C38: 0 | D38: 0 | E38: 0
A39: Care management PMPM ($) | B39: 0 | C39: 55 | D39: 0 | E39: 0
A40: Primary care cap PMPM ($) | B40: 0 | C40: 0 | D40: 0 | E40: 80
A41: FFS own-services PMPM ($) | B41: 0 | C41: 0 | D41: 50 | E41: 0
A42: TCOC target / benchmark (% of prem) | B42: 0 | C42: 0.88 | D42: 0.9 | E42: 0.98
A43: Provider savings split | B43: 0 | C43: 0.5 | D43: 0.6 | E43: 0.5
A44: Provider loss split | B44: 0 | C44: 0.5 | D44: 0 | E44: 0.5
...

Sheet A. Full Cap
A1: CONTRACT A — Full / Global Capitation (100% TCOC risk)
A2: ($ unless noted) | C2: Jan | D2: Feb | E2: Mar | F2: Apr | G2: May | H2: Jun | I2: Jul | J2: Aug | K2: Sep | L2: Oct | M2: Nov | N2: Dec | O2: Year 1
A3: MEMBERSHIP
A4: Members — beginning | C4: =Assumptions!$B$34 -> 3600 | D4: =C5 -> 3636 | E4: =D5 -> 3672.36 | F4: =E5 -> 3709.0836 | G4: =F5 -> 3746.1744 | H4: =G5 -> 3783.6362 | I4: =H5 -> 3821.4725 | J4: =I5 -> 3859.6873 | K4: =J5 -> 3898.2841 | ... N4: =M5 -> 4016.406
A5: Members — ending | C5: =C4*(1+Assumptions!$B$35) -> 3636 | D5: =D4*(1+Assumptions!$B$35) -> 3672.36 | E5: =E4*(1+Assumptions!$B$35) -> 3709.0836 | F5: =F4*(1+Assumptions!$B$35) -> 3746.1744 | G5: =G4*(1+Assumptions!$B$35) -> 3783.6362 | H5: =H4*(1+Assumptions!$B$35) -> 3821.4725 | I5: =I4*(1+Assumptions!$B$35) -> 3859.6873 | J5: =J4*(1+Assumptions!$B$35) -> 3898.2841 | ... N5: =N4*(1+Assumptions!$B$35) -> 4056.5701 | O5: =N5 -> 4056.5701
A6: Member-months (avg) | C6: =AVERAGE(C4,C5) -> 3618 | D6: =AVERAGE(D4,D5) -> 3654.18 | E6: =AVERAGE(E4,E5) -> 3690.7218 | F6: =AVERAGE(F4,F5) -> 3727.629 | G6: =AVERAGE(G4,G5) -> 3764.9053 | H6: =AVERAGE(H4,H5) -> 3802.5544 | I6: =AVERAGE(I4,I5) -> 3840.5799 | J6: =AVERAGE(J4,J5) -> 3878.9857 | ... N6: =AVERAGE(N4,N5) -> 4036.4881 | O6: =SUM(C6:N6) -> 45885.296
A8: LEVERS — RISK & TCOC
A9: RAF (risk score, Yr-1 cohort) | C9: =Assumptions!$B$36*Assumptions!$B$52 -> 1.008 | D9: =Assumptions!$B$36*Assumptions!$B$52 -> 1.008 | E9: =Assumptions!$B$36*Assumptions!$B$52 -> 1.008 | F9: =Assumptions!$B$36*Assumptions!$B$52 -> 1.008 | G9: =Assumptions!$B$36*Assumptions!$B$52 -> 1.008 | H9: =Assumptions!$B$36*Assumptions!$B$52 -> 1.008 | I9: =Assumptions!$B$36*Assumptions!$B$52 -> 1.008 | J9: =Assumptions!$B$36*Assumptions!$B$52 -> 1.008 | ... N9: =Assumptions!$B$36*Assumptions!$B$52 -> 1.008
A10: Premium / benchmark PMPM | C10: =Assumptions!$B$37 -> 1450 | D10: =Assumptions!$B$37 -> 1450 | E10: =Assumptions!$B$37 -> 1450 | F10: =Assumptions!$B$37 -> 1450 | G10: =Assumptions!$B$37 -> 1450 | H10: =Assumptions!$B$37 -> 1450 | I10: =Assumptions!$B$37 -> 1450 | J10: =Assumptions!$B$37 -> 1450 | ... N10: =Assumptions!$B$37 -> 1450
A11: New-clinic TCOC factor | C11: =Assumptions!$B$9+(Assumptions!$B$10-Assumptions!$B$9)*(0)/11 -> 1.06 | D11: =Assumptions!$B$9+(Assumptions!$B$10-Assumptions!$B$9)*(1)/11 -> 1.0545455 | E11: =Assumptions!$B$9+(Assumptions!$B$10-Assumptions!$B$9)*(2)/11 -> 1.0490909 | F11: =Assumptions!$B$9+(Assumptions!$B$10-Assumptions!$B$9)*(3)/11 -> 1.0436364 | G11: =Assumptions!$B$9+(Assumptions!$B$10-Assumptions!$B$9)*(4)/11 -> 1.0381818 | H11: =Assumptions!$B$9+(Assumptions!$B$10-Assumptions!$B$9)*(5)/11 -> 1.0327273 | I11: =Assumptions!$B$9+(Assumptions!$B$10-Assumptions!$B$9)*(6)/11 -> 1.0272727 | J11: =Assumptions!$B$9+(Assumptions!$B$10-Assumptions!$B$9)*(7)/11 -> 1.0218182 | K11: =Assumptions!$B$9+(Assumptions!$B$10-Assumptions!$B$9)*(8)/11 -> 1.0163636 | L11: =Assumptions!$B$9+(Assumptions!$B$10-Assumptions!$B$9)*(9)/11 -> 1.0109091 | M11: =Assumptions!$B$9+(Assumptions!$B$10-Assumptions!$B$9)*(10)/11 -> 1.0054545 | N11: =Assumptions!$B$9+(Assumptions!$B$10-Assumptions!$B$9)*(11)/11 -> 1
A12: Actual TCOC PMPM | C12: =Assumptions!$B$46*C11 -> 1208.4 | D12: =Assumptions!$B$46*D11 -> 1202.1818 | E12: =Assumptions!$B$46*E11 -> 1195.9636 | F12: =Assumptions!$B$46*F11 -> 1189.7455 | G12: =Assumptions!$B$46*G11 -> 1183.5273 | H12: =Assumptions!$B$46*H11 -> 1177.3091 | I12: =Assumptions!$B$46*I11 -> 1171.0909 | J12: =Assumptions!$B$46*J11 -> 1164.8727 | ... N12: =Assumptions!$B$46*N11 -> 1140
A14: REVENUE
A15: Global capitation | C15: =C6*C10*C9*Assumptions!$B$38 -> 4759261.9 | D15: =D6*D10*D9*Assumptions!$B$38 -> 4806854.5 | E15: =E6*E10*E9*Assumptions!$B$38 -> 4854923.1 | F15: =F6*F10*F9*Assumptions!$B$38 -> 4903472.3 | G15: =G6*G10*G9*Assumptions!$B$38 -> 4952507 | H15: =H6*H10*H9*Assumptions!$B$38 -> 5002032.1 | I15: =I6*I10*I9*Assumptions!$B$38 -> 5052052.4 | J15: =J6*J10*J9*Assumptions!$B$38 -> 5102573 | ... N15: =N6*N10*N9*Assumptions!$B$38 -> 5309757.9 | O15: =SUM(C15:N15) -> 60359354
A16: Care management | C16: =C6*Assumptions!$B$39 -> 0 | D16: =D6*Assumptions!$B$39 -> 0 | E16: =E6*Assumptions!$B$39 -> 0 | F16: =F6*Assumptions!$B$39 -> 0 | G16: =G6*Assumptions!$B$39 -> 0 | H16: =H6*Assumptions!$B$39 -> 0 | I16: =I6*Assumptions!$B$39 -> 0 | J16: =J6*Assumptions!$B$39 -> 0 | ... N16: =N6*Assumptions!$B$39 -> 0 | O16: =SUM(C16:N16) -> 0
A17: Primary care cap (PCCP) | C17: =C6*Assumptions!$B$40 -> 0 | D17: =D6*Assumptions!$B$40 -> 0 | E17: =E6*Assumptions!$B$40 -> 0 | F17: =F6*Assumptions!$B$40 -> 0 | G17: =G6*Assumptions!$B$40 -> 0 | H17: =H6*Assumptions!$B$40 -> 0 | I17: =I6*Assumptions!$B$40 -> 0 | J17: =J6*Assumptions!$B$40 -> 0 | ... N17: =N6*Assumptions!$B$40 -> 0 | O17: =SUM(C17:N17) -> 0
A18: FFS own services | C18: =C6*Assumptions!$B$41 -> 0 | D18: =D6*Assumptions!$B$41 -> 0 | E18: =E6*Assumptions!$B$41 -> 0 | F18: =F6*Assumptions!$B$41 -> 0 | G18: =G6*Assumptions!$B$41 -> 0 | H18: =H6*Assumptions!$B$41 -> 0 | I18: =I6*Assumptions!$B$41 -> 0 | J18: =J6*Assumptions!$B$41 -> 0 | ... N18: =N6*Assumptions!$B$41 -> 0 | O18: =SUM(C18:N18) -> 0
A19: Benchmark / target TCOC (memo) | C19: =C6*C10*C9*Assumptions!$B$42 -> 0 | D19: =D6*D10*D9*Assumptions!$B$42 -> 0 | E19: =E6*E10*E9*Assumptions!$B$42 -> 0 | F19: =F6*F10*F9*Assumptions!$B$42 -> 0 | G19: =G6*G10*G9*Assumptions!$B$42 -> 0 | H19: =H6*H10*H9*Assumptions!$B$42 -> 0 | I19: =I6*I10*I9*Assumptions!$B$42 -> 0 | J19: =J6*J10*J9*Assumptions!$B$42 -> 0 | ... N19: =N6*N10*N9*Assumptions!$B$42 -> 0 | O19: =SUM(C19:N19) -> 0
A20: Actual TCOC (memo) | C20: =C6*C12 -> 4371991.2 | D20: =D6*D12 -> 4392988.8 | E20: =E6*E12 -> 4413969.1 | F20: =F6*F12 -> 4434929.7 | G20: =G6*G12 -> 4455868.1 | H20: =H6*H12 -> 4476781.8 | I20: =I6*I12 -> 4497668.2 | J20: =J6*J12 -> 4518524.7 | ... N20: =N6*N12 -> 4601596.4 | O20: =SUM(C20:N20) -> 53844690
A21: Gross savings vs benchmark (memo) | C21: =C19-C20 -> -4371991.2 | D21: =D19-D20 -> -4392988.8 | E21: =E19-E20 -> -4413969.1 | F21: =F19-F20 -> -4434929.7 | G21: =G19-G20 -> -4455868.1 | H21: =H19-H20 -> -4476781.8 | I21: =I19-I20 -> -4497668.2 | J21: =J19-J20 -> -4518524.7 | ... N21: =N19-N20 -> -4601596.4 | O21: =SUM(C21:N21) -> -53844690
A22: Shared savings / (loss) settlement | C22: =IF(Assumptions!$B$33=1,0,IF(C21>=0,C21*Assumptions!$B$43,C21*Assumptions!$B$44*Assumptions!$B$45)) -> 0 | D22: =IF(Assumptions!$B$33=1,0,IF(D21>=0,D21*Assumptions!$B$43,D21*Assumptions!$B$44*Assumptions!$B$45)) -> 0 | E22: =IF(Assumptions!$B$33=1,0,IF(E21>=0,E21*Assumptions!$B$43,E21*Assumptions!$B$44*Assumptions!$B$45)) -> 0 | F22: =IF(Assumptions!$B$33=1,0,IF(F21>=0,F21*Assumptions!$B$43,F21*Assumptions!$B$44*Assumptions!$B$45)) -> 0 | G22: =IF(Assumptions!$B$33=1,0,IF(G21>=0,G21*Assumptions!$B$43,G21*Assumptions!$B$44*Assumptions!$B$45)) -> 0 | H22: =IF(Assumptions!$B$33=1,0,IF(H21>=0,H21*Assumptions!$B$43,H21*Assumptions!$B$44*Assumptions!$B$45)) -> 0 | I22: =IF(Assumptions!$B$33=1,0,IF(I21>=0,I21*Assumptions!$B$43,I21*Assumptions!$B$44*Assumptions!$B$45)) -> 0 | J22: =IF(Assumptions!$B$33=1,0,IF(J21>=0,J21*Assumptions!$B$43,J21*Assumptions!$B$44*Assumptions!$B$45)) -> 0 | ... N22: =IF(Assumptions!$B$33=1,0,IF(N21>=0,N21*Assumptions!$B$43,N21*Assumptions!$B$44*Assumptions!$B$45)) -> 0 | O22: =SUM(C22:N22) -> 0
A23: TOTAL PROVIDER REVENUE | C23: =C15+C16+C17+C18+C22 -> 4759261.9 | D23: =D15+D16+D17+D18+D22 -> 4806854.5 | E23: =E15+E16+E17+E18+E22 -> 4854923.1 | F23: =F15+F16+F17+F18+F22 -> 4903472.3 | G23: =G15+G16+G17+G18+G22 -> 4952507 | H23: =H15+H16+H17+H18+H22 -> 5002032.1 | I23: =I15+I16+I17+I18+I22 -> 5052052.4 | J23: =J15+J16+J17+J18+J22 -> 5102573 | ... N23: =N15+N16+N17+N18+N22 -> 5309757.9 | O23: =SUM(C23:N23) -> 60359354
A25: PROVIDER MEDICAL COST (cash-bearing)
A26: Medical claims (full-cap only) | C26: =Assumptions!$B$33*C20 -> 4371991.2 | D26: =Assumptions!$B$33*D20 -> 4392988.8 | E26: =Assumptions!$B$33*E20 -> 4413969.1 | F26: =Assumptions!$B$33*F20 -> 4434929.7 | G26: =Assumptions!$B$33*G20 -> 4455868.1 | H26: =Assumptions!$B$33*H20 -> 4476781.8 | I26: =Assumptions!$B$33*I20 -> 4497668.2 | J26: =Assumptions!$B$33*J20 -> 4518524.7 | ... N26: =Assumptions!$B$33*N20 -> 4601596.4 | O26: =SUM(C26:N26) -> 53844690
A27: Stop-loss premium | C27: =Assumptions!$B$33*C6*Assumptions!$B$47 -> 126630 | D27: =Assumptions!$B$33*D6*Assumptions!$B$47 -> 127896.3 | E27: =Assumptions!$B$33*E6*Assumptions!$B$47 -> 129175.26 | F27: =Assumptions!$B$33*F6*Assumptions!$B$47 -> 130467.02 | G27: =Assumptions!$B$33*G6*Assumptions!$B$47 -> 131771.69 | H27: =Assumptions!$B$33*H6*Assumptions!$B$47 -> 133089.4 | I27: =Assumptions!$B$33*I6*Assumptions!$B$47 -> 134420.3 | J27: =Assumptions!$B$33*J6*Assumptions!$B$47 -> 135764.5 | ... N27: =Assumptions!$B$33*N6*Assumptions!$B$47 -> 141277.08 | O27: =SUM(C27:N27) -> 1605985.4
A28: Stop-loss recoveries | C28: =-Assumptions!$B$33*C6*Assumptions!$B$48 -> -94068 | D28: =-Assumptions!$B$33*D6*Assumptions!$B$48 -> -95008.68 | E28: =-Assumptions!$B$33*E6*Assumptions!$B$48 -> -95958.767 | F28: =-Assumptions!$B$33*F6*Assumptions!$B$48 -> -96918.354 | G28: =-Assumptions!$B$33*G6*Assumptions!$B$48 -> -97887.538 | H28: =-Assumptions!$B$33*H6*Assumptions!$B$48 -> -98866.413 | I28: =-Assumptions!$B$33*I6*Assumptions!$B$48 -> -99855.078 | J28: =-Assumptions!$B$33*J6*Assumptions!$B$48 -> -100853.63 | ... N28: =-Assumptions!$B$33*N6*Assumptions!$B$48 -> -104948.69 | O28: =SUM(C28:N28) -> -1193017.7
A29: TOTAL PROVIDER MEDICAL COST | C29: =C26+C27+C28 -> 4404553.2 | D29: =D26+D27+D28 -> 4425876.4 | E29: =E26+E27+E28 -> 4447185.6 | F29: =F26+F27+F28 -> 4468478.3 | G29: =G26+G27+G28 -> 4489752.3 | H29: =H26+H27+H28 -> 4511004.8 | I29: =I26+I27+I28 -> 4532233.4 | J29: =J26+J27+J28 -> 4553435.5 | ... N29: =N26+N27+N28 -> 4637924.8 | O29: =SUM(C29:N29) -> 54257658
A31: CONTRIBUTION & RATIOS
A32: Contribution margin | C32: =C23-C29 -> 354708.72 | D32: =D23-D29 -> 380978.16 | E32: =E23-E29 -> 407737.52 | F32: =F23-F29 -> 434993.97 | G32: =G23-G29 -> 462754.78 | H32: =H23-H29 -> 491027.3 | I32: =I23-I29 -> 519819 | J32: =J23-J29 -> 549137.43 | ... N32: =N23-N29 -> 671833.08 | O32: =SUM(C32:N32) -> 6101695.6
A33: Medical loss ratio (TCOC / premium) | C33: =IF(C6=0,0,C20/(C6*C10*C9)) -> 0.82676519 | D33: =IF(D6=0,0,D20/(D6*D10*D9)) -> 0.82251082 | E33: =IF(E6=0,0,E20/(E6*E10*E9)) -> 0.81825646 | F33: =IF(F6=0,0,F20/(F6*F10*F9)) -> 0.81400209 | G33: =IF(G6=0,0,G20/(G6*G10*G9)) -> 0.80974772 | H33: =IF(H6=0,0,H20/(H6*H10*H9)) -> 0.80549336 | I33: =IF(I6=0,0,I20/(I6*I10*I9)) -> 0.80123899 | J33: =IF(J6=0,0,J20/(J6*J10*J9)) -> 0.79698462 | ... N33: =IF(N6=0,0,N20/(N6*N10*N9)) -> 0.77996716 | O33: =O20/SUMPRODUCT(C6:N6,C10:N10,C9:N9) -> 0.80286183
A34: Contribution PMPM | C34: =IF(C6=0,0,C32/C6) -> 98.04 | D34: =IF(D6=0,0,D32/D6) -> 104.25818 | E34: =IF(E6=0,0,E32/E6) -> 110.47636 | F34: =IF(F6=0,0,F32/F6) -> 116.69455 | G34: =IF(G6=0,0,G32/G6) -> 122.91273 | H34: =IF(H6=0,0,H32/H6) -> 129.13091 | I34: =IF(I6=0,0,I32/I6) -> 135.34909 | J34: =IF(J6=0,0,J32/J6) -> 141.56727 | ... N34: =IF(N6=0,0,N32/N6) -> 166.44 | O34: =O32/O6 -> 132.97714

Sheet B. Two-Sided
A1: CONTRACT B — Two-Sided Shared Risk (50/50 vs target)
A2: ($ unless noted) | C2: Jan | D2: Feb | E2: Mar | F2: Apr | G2: May | H2: Jun | I2: Jul | J2: Aug | K2: Sep | L2: Oct | M2: Nov | N2: Dec | O2: Year 1
A3: MEMBERSHIP
A4: Members — beginning | C4: =Assumptions!$C$34 -> 450 | D4: =C5 -> 454.5 | E4: =D5 -> 459.045 | F4: =E5 -> 463.63545 | G4: =F5 -> 468.2718 | H4: =G5 -> 472.95452 | I4: =H5 -> 477.68407 | J4: =I5 -> 482.46091 | K4: =J5 -> 487.28552 | ... N4: =M5 -> 502.05076
A5: Members — ending | C5: =C4*(1+Assumptions!$C$35) -> 454.5 | D5: =D4*(1+Assumptions!$C$35) -> 459.045 | E5: =E4*(1+Assumptions!$C$35) -> 463.63545 | F5: =F4*(1+Assumptions!$C$35) -> 468.2718 | G5: =G4*(1+Assumptions!$C$35) -> 472.95452 | H5: =H4*(1+Assumptions!$C$35) -> 477.68407 | I5: =I4*(1+Assumptions!$C$35) -> 482.46091 | J5: =J4*(1+Assumptions!$C$35) -> 487.28552 | ... N5: =N4*(1+Assumptions!$C$35) -> 507.07126 | O5: =N5 -> 507.07126
A6: Member-months (avg) | C6: =AVERAGE(C4,C5) -> 452.25 | D6: =AVERAGE(D4,D5) -> 456.7725 | E6: =AVERAGE(E4,E5) -> 461.34022 | F6: =AVERAGE(F4,F5) -> 465.95363 | G6: =AVERAGE(G4,G5) -> 470.61316 | H6: =AVERAGE(H4,H5) -> 475.3193 | I6: =AVERAGE(I4,I5) -> 480.07249 | J6: =AVERAGE(J4,J5) -> 484.87321 | ... N6: =AVERAGE(N4,N5) -> 504.56101 | O6: =SUM(C6:N6) -> 5735.662
A8: LEVERS — RISK & TCOC
A9: RAF (risk score, Yr-1 cohort) | C9: =Assumptions!$C$36*Assumptions!$B$52 -> 0.945 | D9: =Assumptions!$C$36*Assumptions!$B$52 -> 0.945 | E9: =Assumptions!$C$36*Assumptions!$B$52 -> 0.945 | F9: =Assumptions!$C$36*Assumptions!$B$52 -> 0.945 | G9: =Assumptions!$C$36*Assumptions!$B$52 -> 0.945 | H9: =Assumptions!$C$36*Assumptions!$B$52 -> 0.945 | I9: =Assumptions!$C$36*Assumptions!$B$52 -> 0.945 | J9: =Assumptions!$C$36*Assumptions!$B$52 -> 0.945 | ... N9: =Assumptions!$C$36*Assumptions!$B$52 -> 0.945
A10: Premium / benchmark PMPM | C10: =Assumptions!$C$37 -> 1350 | D10: =Assumptions!$C$37 -> 1350 | E10: =Assumptions!$C$37 -> 1350 | F10: =Assumptions!$C$37 -> 1350 | G10: =Assumptions!$C$37 -> 1350 | H10: =Assumptions!$C$37 -> 1350 | I10: =Assumptions!$C$37 -> 1350 | J10: =Assumptions!$C$37 -> 1350 | ... N10: =Assumptions!$C$37 -> 1350
A11: New-clinic TCOC factor | C11: =Assumptions!$B$9+(Assumptions!$B$10-Assumptions!$B$9)*(0)/11 -> 1.06 | D11: =Assumptions!$B$9+(Assumptions!$B$10-Assumptions!$B$9)*(1)/11 -> 1.0545455 | E11: =Assumptions!$B$9+(Assumptions!$B$10-Assumptions!$B$9)*(2)/11 -> 1.0490909 | F11: =Assumptions!$B$9+(Assumptions!$B$10-Assumptions!$B$9)*(3)/11 -> 1.0436364 | G11: =Assumptions!$B$9+(Assumptions!$B$10-Assumptions!$B$9)*(4)/11 -> 1.0381818 | H11: =Assumptions!$B$9+(Assumptions!$B$10-Assumptions!$B$9)*(5)/11 -> 1.0327273 | I11: =Assumptions!$B$9+(Assumptions!$B$10-Assumptions!$B$9)*(6)/11 -> 1.0272727 | J11: =Assumptions!$B$9+(Assumptions!$B$10-Assumptions!$B$9)*(7)/11 -> 1.0218182 | K11: =Assumptions!$B$9+(Assumptions!$B$10-Assumptions!$B$9)*(8)/11 -> 1.0163636 | L11: =Assumptions!$B$9+(Assumptions!$B$10-Assumptions!$B$9)*(9)/11 -> 1.0109091 | M11: =Assumptions!$B$9+(Assumptions!$B$10-Assumptions!$B$9)*(10)/11 -> 1.0054545 | N11: =Assumptions!$B$9+(Assumptions!$B$10-Assumptions!$B$9)*(11)/11 -> 1
A12: Actual TCOC PMPM | C12: =Assumptions!$C$46*C11 -> 1187.2 | D12: =Assumptions!$C$46*D11 -> 1181.0909 | E12: =Assumptions!$C$46*E11 -> 1174.9818 | F12: =Assumptions!$C$46*F11 -> 1168.8727 | G12: =Assumptions!$C$46*G11 -> 1162.7636 | H12: =Assumptions!$C$46*H11 -> 1156.6545 | I12: =Assumptions!$C$46*I11 -> 1150.5455 | J12: =Assumptions!$C$46*J11 -> 1144.4364 | ... N12: =Assumptions!$C$46*N11 -> 1120
A14: REVENUE
A15: Global capitation | C15: =C6*C10*C9*Assumptions!$C$38 -> 0 | D15: =D6*D10*D9*Assumptions!$C$38 -> 0 | E15: =E6*E10*E9*Assumptions!$C$38 -> 0 | F15: =F6*F10*F9*Assumptions!$C$38 -> 0 | G15: =G6*G10*G9*Assumptions!$C$38 -> 0 | H15: =H6*H10*H9*Assumptions!$C$38 -> 0 | I15: =I6*I10*I9*Assumptions!$C$38 -> 0 | J15: =J6*J10*J9*Assumptions!$C$38 -> 0 | ... N15: =N6*N10*N9*Assumptions!$C$38 -> 0 | O15: =SUM(C15:N15) -> 0
A16: Care management | C16: =C6*Assumptions!$C$39 -> 24873.75 | D16: =D6*Assumptions!$C$39 -> 25122.487 | E16: =E6*Assumptions!$C$39 -> 25373.712 | F16: =F6*Assumptions!$C$39 -> 25627.449 | G16: =G6*Assumptions!$C$39 -> 25883.724 | H16: =H6*Assumptions!$C$39 -> 26142.561 | I16: =I6*Assumptions!$C$39 -> 26403.987 | J16: =J6*Assumptions!$C$39 -> 26668.027 | ... N16: =N6*Assumptions!$C$39 -> 27750.856 | O16: =SUM(C16:N16) -> 315461.41
A17: Primary care cap (PCCP) | C17: =C6*Assumptions!$C$40 -> 0 | D17: =D6*Assumptions!$C$40 -> 0 | E17: =E6*Assumptions!$C$40 -> 0 | F17: =F6*Assumptions!$C$40 -> 0 | G17: =G6*Assumptions!$C$40 -> 0 | H17: =H6*Assumptions!$C$40 -> 0 | I17: =I6*Assumptions!$C$40 -> 0 | J17: =J6*Assumptions!$C$40 -> 0 | ... N17: =N6*Assumptions!$C$40 -> 0 | O17: =SUM(C17:N17) -> 0
A18: FFS own services | C18: =C6*Assumptions!$C$41 -> 0 | D18: =D6*Assumptions!$C$41 -> 0 | E18: =E6*Assumptions!$C$41 -> 0 | F18: =F6*Assumptions!$C$41 -> 0 | G18: =G6*Assumptions!$C$41 -> 0 | H18: =H6*Assumptions!$C$41 -> 0 | I18: =I6*Assumptions!$C$41 -> 0 | J18: =J6*Assumptions!$C$41 -> 0 | ... N18: =N6*Assumptions!$C$41 -> 0 | O18: =SUM(C18:N18) -> 0
A19: Benchmark / target TCOC (memo) | C19: =C6*C10*C9*Assumptions!$C$42 -> 507722.98 | D19: =D6*D10*D9*Assumptions!$C$42 -> 512800.21 | E19: =E6*E10*E9*Assumptions!$C$42 -> 517928.22 | F19: =F6*F10*F9*Assumptions!$C$42 -> 523107.5 | G19: =G6*G10*G9*Assumptions!$C$42 -> 528338.57 | H19: =H6*H10*H9*Assumptions!$C$42 -> 533621.96 | I19: =I6*I10*I9*Assumptions!$C$42 -> 538958.18 | J19: =J6*J10*J9*Assumptions!$C$42 -> 544347.76 | ... N19: =N6*N10*N9*Assumptions!$C$42 -> 566450.46 | O19: =SUM(C19:N19) -> 6439198.3
A20: Actual TCOC (memo) | C20: =C6*C12 -> 536911.2 | D20: =D6*D12 -> 539489.85 | E20: =E6*E12 -> 542066.38 | F20: =F6*F12 -> 544640.49 | G20: =G6*G12 -> 547211.87 | H20: =H6*H12 -> 549780.22 | I20: =I6*I12 -> 552345.22 | J20: =J6*J12 -> 554906.54 | ... N20: =N6*N12 -> 565108.33 | O20: =SUM(C20:N20) -> 6612505.8
A21: Gross savings vs benchmark (memo) | C21: =C19-C20 -> -29188.215 | D21: =D19-D20 -> -26689.632 | E21: =E19-E20 -> -24138.159 | F21: =F19-F20 -> -21532.988 | G21: =G19-G20 -> -18873.299 | H21: =H19-H20 -> -16158.263 | I21: =I19-I20 -> -13387.04 | J21: =J19-J20 -> -10558.775 | ... N21: =N19-N20 -> 1342.1323 | O21: =SUM(C21:N21) -> -173307.55
A22: Shared savings / (loss) settlement | C22: =IF(Assumptions!$C$33=1,0,IF(C21>=0,C21*Assumptions!$C$43,C21*Assumptions!$C$44*Assumptions!$C$45)) -> -14594.108 | D22: =IF(Assumptions!$C$33=1,0,IF(D21>=0,D21*Assumptions!$C$43,D21*Assumptions!$C$44*Assumptions!$C$45)) -> -13344.816 | E22: =IF(Assumptions!$C$33=1,0,IF(E21>=0,E21*Assumptions!$C$43,E21*Assumptions!$C$44*Assumptions!$C$45)) -> -12069.08 | F22: =IF(Assumptions!$C$33=1,0,IF(F21>=0,F21*Assumptions!$C$43,F21*Assumptions!$C$44*Assumptions!$C$45)) -> -10766.494 | G22: =IF(Assumptions!$C$33=1,0,IF(G21>=0,G21*Assumptions!$C$43,G21*Assumptions!$C$44*Assumptions!$C$45)) -> -9436.6496 | H22: =IF(Assumptions!$C$33=1,0,IF(H21>=0,H21*Assumptions!$C$43,H21*Assumptions!$C$44*Assumptions!$C$45)) -> -8079.1317 | I22: =IF(Assumptions!$C$33=1,0,IF(I21>=0,I21*Assumptions!$C$43,I21*Assumptions!$C$44*Assumptions!$C$45)) -> -6693.5198 | J22: =IF(Assumptions!$C$33=1,0,IF(J21>=0,J21*Assumptions!$C$43,J21*Assumptions!$C$44*Assumptions!$C$45)) -> -5279.3877 | ... N22: =IF(Assumptions!$C$33=1,0,IF(N21>=0,N21*Assumptions!$C$43,N21*Assumptions!$C$44*Assumptions!$C$45)) -> 671.06614 | O22: =SUM(C22:N22) -> -86653.777
A23: TOTAL PROVIDER REVENUE | C23: =C15+C16+C17+C18+C22 -> 10279.642 | D23: =D15+D16+D17+D18+D22 -> 11777.671 | E23: =E15+E16+E17+E18+E22 -> 13304.633 | F23: =F15+F16+F17+F18+F22 -> 14860.956 | G23: =G15+G16+G17+G18+G22 -> 16447.074 | H23: =H15+H16+H17+H18+H22 -> 18063.43 | I23: =I15+I16+I17+I18+I22 -> 19710.467 | J23: =J15+J16+J17+J18+J22 -> 21388.639 | ... N23: =N15+N16+N17+N18+N22 -> 28421.922 | O23: =SUM(C23:N23) -> 228807.63
A25: PROVIDER MEDICAL COST (cash-bearing)
A26: Medical claims (full-cap only) | C26: =Assumptions!$C$33*C20 -> 0 | D26: =Assumptions!$C$33*D20 -> 0 | E26: =Assumptions!$C$33*E20 -> 0 | F26: =Assumptions!$C$33*F20 -> 0 | G26: =Assumptions!$C$33*G20 -> 0 | H26: =Assumptions!$C$33*H20 -> 0 | I26: =Assumptions!$C$33*I20 -> 0 | J26: =Assumptions!$C$33*J20 -> 0 | ... N26: =Assumptions!$C$33*N20 -> 0 | O26: =SUM(C26:N26) -> 0
A27: Stop-loss premium | C27: =Assumptions!$C$33*C6*Assumptions!$C$47 -> 0 | D27: =Assumptions!$C$33*D6*Assumptions!$C$47 -> 0 | E27: =Assumptions!$C$33*E6*Assumptions!$C$47 -> 0 | F27: =Assumptions!$C$33*F6*Assumptions!$C$47 -> 0 | G27: =Assumptions!$C$33*G6*Assumptions!$C$47 -> 0 | H27: =Assumptions!$C$33*H6*Assumptions!$C$47 -> 0 | I27: =Assumptions!$C$33*I6*Assumptions!$C$47 -> 0 | J27: =Assumptions!$C$33*J6*Assumptions!$C$47 -> 0 | ... N27: =Assumptions!$C$33*N6*Assumptions!$C$47 -> 0 | O27: =SUM(C27:N27) -> 0
A28: Stop-loss recoveries | C28: =-Assumptions!$C$33*C6*Assumptions!$C$48 -> 0 | D28: =-Assumptions!$C$33*D6*Assumptions!$C$48 -> 0 | E28: =-Assumptions!$C$33*E6*Assumptions!$C$48 -> 0 | F28: =-Assumptions!$C$33*F6*Assumptions!$C$48 -> 0 | G28: =-Assumptions!$C$33*G6*Assumptions!$C$48 -> 0 | H28: =-Assumptions!$C$33*H6*Assumptions!$C$48 -> 0 | I28: =-Assumptions!$C$33*I6*Assumptions!$C$48 -> 0 | J28: =-Assumptions!$C$33*J6*Assumptions!$C$48 -> 0 | ... N28: =-Assumptions!$C$33*N6*Assumptions!$C$48 -> 0 | O28: =SUM(C28:N28) -> 0
A29: TOTAL PROVIDER MEDICAL COST | C29: =C26+C27+C28 -> 0 | D29: =D26+D27+D28 -> 0 | E29: =E26+E27+E28 -> 0 | F29: =F26+F27+F28 -> 0 | G29: =G26+G27+G28 -> 0 | H29: =H26+H27+H28 -> 0 | I29: =I26+I27+I28 -> 0 | J29: =J26+J27+J28 -> 0 | ... N29: =N26+N27+N28 -> 0 | O29: =SUM(C29:N29) -> 0
A31: CONTRIBUTION & RATIOS
A32: Contribution margin | C32: =C23-C29 -> 10279.642 | D32: =D23-D29 -> 11777.671 | E32: =E23-E29 -> 13304.633 | F32: =F23-F29 -> 14860.956 | G32: =G23-G29 -> 16447.074 | H32: =H23-H29 -> 18063.43 | I32: =I23-I29 -> 19710.467 | J32: =J23-J29 -> 21388.639 | ... N32: =N23-N29 -> 28421.922 | O32: =SUM(C32:N32) -> 228807.63
A33: Medical loss ratio (TCOC / premium) | C33: =IF(C6=0,0,C20/(C6*C10*C9)) -> 0.93058985 | D33: =IF(D6=0,0,D20/(D6*D10*D9)) -> 0.92580122 | E33: =IF(E6=0,0,E20/(E6*E10*E9)) -> 0.9210126 | F33: =IF(F6=0,0,F20/(F6*F10*F9)) -> 0.91622397 | G33: =IF(G6=0,0,G20/(G6*G10*G9)) -> 0.91143534 | H33: =IF(H6=0,0,H20/(H6*H10*H9)) -> 0.90664671 | I33: =IF(I6=0,0,I20/(I6*I10*I9)) -> 0.90185809 | J33: =IF(J6=0,0,J20/(J6*J10*J9)) -> 0.89706946 | ... N33: =IF(N6=0,0,N20/(N6*N10*N9)) -> 0.87791495 | O33: =O20/SUMPRODUCT(C6:N6,C10:N10,C9:N9) -> 0.90368473
A34: Contribution PMPM | C34: =IF(C6=0,0,C32/C6) -> 22.73 | D34: =IF(D6=0,0,D32/D6) -> 25.784545 | E34: =IF(E6=0,0,E32/E6) -> 28.839091 | F34: =IF(F6=0,0,F32/F6) -> 31.893636 | G34: =IF(G6=0,0,G32/G6) -> 34.948182 | H34: =IF(H6=0,0,H32/H6) -> 38.002727 | I34: =IF(I6=0,0,I32/I6) -> 41.057273 | J34: =IF(J6=0,0,J32/J6) -> 44.111818 | ... N34: =IF(N6=0,0,N32/N6) -> 56.33 | O34: =O32/O6 -> 39.892105

Sheet C. Upside
A1: CONTRACT C — Upside-Only Shared Savings (60% upside, no downside)
A2: ($ unless noted) | C2: Jan | D2: Feb | E2: Mar | F2: Apr | G2: May | H2: Jun | I2: Jul | J2: Aug | K2: Sep | L2: Oct | M2: Nov | N2: Dec | O2: Year 1
A3: MEMBERSHIP
A4: Members — beginning | C4: =Assumptions!$D$34 -> 250 | D4: =C5 -> 252.5 | E4: =D5 -> 255.025 | F4: =E5 -> 257.57525 | G4: =F5 -> 260.151 | H4: =G5 -> 262.75251 | I4: =H5 -> 265.38004 | J4: =I5 -> 268.03384 | K4: =J5 -> 270.71418 | ... N4: =M5 -> 278.91709
A5: Members — ending | C5: =C4*(1+Assumptions!$D$35) -> 252.5 | D5: =D4*(1+Assumptions!$D$35) -> 255.025 | E5: =E4*(1+Assumptions!$D$35) -> 257.57525 | F5: =F4*(1+Assumptions!$D$35) -> 260.151 | G5: =G4*(1+Assumptions!$D$35) -> 262.75251 | H5: =H4*(1+Assumptions!$D$35) -> 265.38004 | I5: =I4*(1+Assumptions!$D$35) -> 268.03384 | J5: =J4*(1+Assumptions!$D$35) -> 270.71418 | ... N5: =N4*(1+Assumptions!$D$35) -> 281.70626 | O5: =N5 -> 281.70626
A6: Member-months (avg) | C6: =AVERAGE(C4,C5) -> 251.25 | D6: =AVERAGE(D4,D5) -> 253.7625 | E6: =AVERAGE(E4,E5) -> 256.30012 | F6: =AVERAGE(F4,F5) -> 258.86313 | G6: =AVERAGE(G4,G5) -> 261.45176 | H6: =AVERAGE(H4,H5) -> 264.06628 | I6: =AVERAGE(I4,I5) -> 266.70694 | J6: =AVERAGE(J4,J5) -> 269.37401 | ... N6: =AVERAGE(N4,N5) -> 280.31167 | O6: =SUM(C6:N6) -> 3186.4789
A8: LEVERS — RISK & TCOC
A9: RAF (risk score, Yr-1 cohort) | C9: =Assumptions!$D$36*Assumptions!$B$52 -> 0.9 | D9: =Assumptions!$D$36*Assumptions!$B$52 -> 0.9 | E9: =Assumptions!$D$36*Assumptions!$B$52 -> 0.9 | F9: =Assumptions!$D$36*Assumptions!$B$52 -> 0.9 | G9: =Assumptions!$D$36*Assumptions!$B$52 -> 0.9 | H9: =Assumptions!$D$36*Assumptions!$B$52 -> 0.9 | I9: =Assumptions!$D$36*Assumptions!$B$52 -> 0.9 | J9: =Assumptions!$D$36*Assumptions!$B$52 -> 0.9 | ... N9: =Assumptions!$D$36*Assumptions!$B$52 -> 0.9
A10: Premium / benchmark PMPM | C10: =Assumptions!$D$37 -> 1250 | D10: =Assumptions!$D$37 -> 1250 | E10: =Assumptions!$D$37 -> 1250 | F10: =Assumptions!$D$37 -> 1250 | G10: =Assumptions!$D$37 -> 1250 | H10: =Assumptions!$D$37 -> 1250 | I10: =Assumptions!$D$37 -> 1250 | J10: =Assumptions!$D$37 -> 1250 | ... N10: =Assumptions!$D$37 -> 1250
A11: New-clinic TCOC factor | C11: =Assumptions!$B$9+(Assumptions!$B$10-Assumptions!$B$9)*(0)/11 -> 1.06 | D11: =Assumptions!$B$9+(Assumptions!$B$10-Assumptions!$B$9)*(1)/11 -> 1.0545455 | E11: =Assumptions!$B$9+(Assumptions!$B$10-Assumptions!$B$9)*(2)/11 -> 1.0490909 | F11: =Assumptions!$B$9+(Assumptions!$B$10-Assumptions!$B$9)*(3)/11 -> 1.0436364 | G11: =Assumptions!$B$9+(Assumptions!$B$10-Assumptions!$B$9)*(4)/11 -> 1.0381818 | H11: =Assumptions!$B$9+(Assumptions!$B$10-Assumptions!$B$9)*(5)/11 -> 1.0327273 | I11: =Assumptions!$B$9+(Assumptions!$B$10-Assumptions!$B$9)*(6)/11 -> 1.0272727 | J11: =Assumptions!$B$9+(Assumptions!$B$10-Assumptions!$B$9)*(7)/11 -> 1.0218182 | K11: =Assumptions!$B$9+(Assumptions!$B$10-Assumptions!$B$9)*(8)/11 -> 1.0163636 | L11: =Assumptions!$B$9+(Assumptions!$B$10-Assumptions!$B$9)*(9)/11 -> 1.0109091 | M11: =Assumptions!$B$9+(Assumptions!$B$10-Assumptions!$B$9)*(10)/11 -> 1.0054545 | N11: =Assumptions!$B$9+(Assumptions!$B$10-Assumptions!$B$9)*(11)/11 -> 1
A12: Actual TCOC PMPM | C12: =Assumptions!$D$46*C11 -> 1123.6 | D12: =Assumptions!$D$46*D11 -> 1117.8182 | E12: =Assumptions!$D$46*E11 -> 1112.0364 | F12: =Assumptions!$D$46*F11 -> 1106.2545 | G12: =Assumptions!$D$46*G11 -> 1100.4727 | H12: =Assumptions!$D$46*H11 -> 1094.6909 | I12: =Assumptions!$D$46*I11 -> 1088.9091 | J12: =Assumptions!$D$46*J11 -> 1083.1273 | ... N12: =Assumptions!$D$46*N11 -> 1060
A14: REVENUE
A15: Global capitation | C15: =C6*C10*C9*Assumptions!$D$38 -> 0 | D15: =D6*D10*D9*Assumptions!$D$38 -> 0 | E15: =E6*E10*E9*Assumptions!$D$38 -> 0 | F15: =F6*F10*F9*Assumptions!$D$38 -> 0 | G15: =G6*G10*G9*Assumptions!$D$38 -> 0 | H15: =H6*H10*H9*Assumptions!$D$38 -> 0 | I15: =I6*I10*I9*Assumptions!$D$38 -> 0 | J15: =J6*J10*J9*Assumptions!$D$38 -> 0 | ... N15: =N6*N10*N9*Assumptions!$D$38 -> 0 | O15: =SUM(C15:N15) -> 0
A16: Care management | C16: =C6*Assumptions!$D$39 -> 0 | D16: =D6*Assumptions!$D$39 -> 0 | E16: =E6*Assumptions!$D$39 -> 0 | F16: =F6*Assumptions!$D$39 -> 0 | G16: =G6*Assumptions!$D$39 -> 0 | H16: =H6*Assumptions!$D$39 -> 0 | I16: =I6*Assumptions!$D$39 -> 0 | J16: =J6*Assumptions!$D$39 -> 0 | ... N16: =N6*Assumptions!$D$39 -> 0 | O16: =SUM(C16:N16) -> 0
A17: Primary care cap (PCCP) | C17: =C6*Assumptions!$D$40 -> 0 | D17: =D6*Assumptions!$D$40 -> 0 | E17: =E6*Assumptions!$D$40 -> 0 | F17: =F6*Assumptions!$D$40 -> 0 | G17: =G6*Assumptions!$D$40 -> 0 | H17: =H6*Assumptions!$D$40 -> 0 | I17: =I6*Assumptions!$D$40 -> 0 | J17: =J6*Assumptions!$D$40 -> 0 | ... N17: =N6*Assumptions!$D$40 -> 0 | O17: =SUM(C17:N17) -> 0
A18: FFS own services | C18: =C6*Assumptions!$D$41 -> 12562.5 | D18: =D6*Assumptions!$D$41 -> 12688.125 | E18: =E6*Assumptions!$D$41 -> 12815.006 | F18: =F6*Assumptions!$D$41 -> 12943.156 | G18: =G6*Assumptions!$D$41 -> 13072.588 | H18: =H6*Assumptions!$D$41 -> 13203.314 | I18: =I6*Assumptions!$D$41 -> 13335.347 | J18: =J6*Assumptions!$D$41 -> 13468.7 | ... N18: =N6*Assumptions!$D$41 -> 14015.584 | O18: =SUM(C18:N18) -> 159323.94
A19: Benchmark / target TCOC (memo) | C19: =C6*C10*C9*Assumptions!$D$42 -> 254390.62 | D19: =D6*D10*D9*Assumptions!$D$42 -> 256934.53 | E19: =E6*E10*E9*Assumptions!$D$42 -> 259503.88 | F19: =F6*F10*F9*Assumptions!$D$42 -> 262098.92 | G19: =G6*G10*G9*Assumptions!$D$42 -> 264719.9 | H19: =H6*H10*H9*Assumptions!$D$42 -> 267367.1 | I19: =I6*I10*I9*Assumptions!$D$42 -> 270040.77 | J19: =J6*J10*J9*Assumptions!$D$42 -> 272741.18 | ... N19: =N6*N10*N9*Assumptions!$D$42 -> 283815.57 | O19: =SUM(C19:N19) -> 3226309.9
A20: Actual TCOC (memo) | C20: =C6*C12 -> 282304.5 | D20: =D6*D12 -> 283660.34 | E20: =E6*E12 -> 285015.06 | F20: =F6*F12 -> 286368.51 | G20: =G6*G12 -> 287720.53 | H20: =H6*H12 -> 289070.95 | I20: =I6*I12 -> 290419.61 | J20: =J6*J12 -> 291766.33 | ... N20: =N6*N12 -> 297130.37 | O20: =SUM(C20:N20) -> 3476813.6
A21: Gross savings vs benchmark (memo) | C21: =C19-C20 -> -27913.875 | D21: =D19-D20 -> -26725.805 | E21: =E19-E20 -> -25511.182 | F21: =F19-F20 -> -24269.595 | G21: =G19-G20 -> -23000.624 | H21: =H19-H20 -> -21703.847 | I21: =I19-I20 -> -20378.835 | J21: =J19-J20 -> -19025.151 | ... N21: =N19-N20 -> -13314.804 | O21: =SUM(C21:N21) -> -250503.72
A22: Shared savings / (loss) settlement | C22: =IF(Assumptions!$D$33=1,0,IF(C21>=0,C21*Assumptions!$D$43,C21*Assumptions!$D$44*Assumptions!$D$45)) -> 0 | D22: =IF(Assumptions!$D$33=1,0,IF(D21>=0,D21*Assumptions!$D$43,D21*Assumptions!$D$44*Assumptions!$D$45)) -> 0 | E22: =IF(Assumptions!$D$33=1,0,IF(E21>=0,E21*Assumptions!$D$43,E21*Assumptions!$D$44*Assumptions!$D$45)) -> 0 | F22: =IF(Assumptions!$D$33=1,0,IF(F21>=0,F21*Assumptions!$D$43,F21*Assumptions!$D$44*Assumptions!$D$45)) -> 0 | G22: =IF(Assumptions!$D$33=1,0,IF(G21>=0,G21*Assumptions!$D$43,G21*Assumptions!$D$44*Assumptions!$D$45)) -> 0 | H22: =IF(Assumptions!$D$33=1,0,IF(H21>=0,H21*Assumptions!$D$43,H21*Assumptions!$D$44*Assumptions!$D$45)) -> 0 | I22: =IF(Assumptions!$D$33=1,0,IF(I21>=0,I21*Assumptions!$D$43,I21*Assumptions!$D$44*Assumptions!$D$45)) -> 0 | J22: =IF(Assumptions!$D$33=1,0,IF(J21>=0,J21*Assumptions!$D$43,J21*Assumptions!$D$44*Assumptions!$D$45)) -> 0 | ... N22: =IF(Assumptions!$D$33=1,0,IF(N21>=0,N21*Assumptions!$D$43,N21*Assumptions!$D$44*Assumptions!$D$45)) -> 0 | O22: =SUM(C22:N22) -> 0
A23: TOTAL PROVIDER REVENUE | C23: =C15+C16+C17+C18+C22 -> 12562.5 | D23: =D15+D16+D17+D18+D22 -> 12688.125 | E23: =E15+E16+E17+E18+E22 -> 12815.006 | F23: =F15+F16+F17+F18+F22 -> 12943.156 | G23: =G15+G16+G17+G18+G22 -> 13072.588 | H23: =H15+H16+H17+H18+H22 -> 13203.314 | I23: =I15+I16+I17+I18+I22 -> 13335.347 | J23: =J15+J16+J17+J18+J22 -> 13468.7 | ... N23: =N15+N16+N17+N18+N22 -> 14015.584 | O23: =SUM(C23:N23) -> 159323.94
A25: PROVIDER MEDICAL COST (cash-bearing)
A26: Medical claims (full-cap only) | C26: =Assumptions!$D$33*C20 -> 0 | D26: =Assumptions!$D$33*D20 -> 0 | E26: =Assumptions!$D$33*E20 -> 0 | F26: =Assumptions!$D$33*F20 -> 0 | G26: =Assumptions!$D$33*G20 -> 0 | H26: =Assumptions!$D$33*H20 -> 0 | I26: =Assumptions!$D$33*I20 -> 0 | J26: =Assumptions!$D$33*J20 -> 0 | ... N26: =Assumptions!$D$33*N20 -> 0 | O26: =SUM(C26:N26) -> 0
A27: Stop-loss premium | C27: =Assumptions!$D$33*C6*Assumptions!$D$47 -> 0 | D27: =Assumptions!$D$33*D6*Assumptions!$D$47 -> 0 | E27: =Assumptions!$D$33*E6*Assumptions!$D$47 -> 0 | F27: =Assumptions!$D$33*F6*Assumptions!$D$47 -> 0 | G27: =Assumptions!$D$33*G6*Assumptions!$D$47 -> 0 | H27: =Assumptions!$D$33*H6*Assumptions!$D$47 -> 0 | I27: =Assumptions!$D$33*I6*Assumptions!$D$47 -> 0 | J27: =Assumptions!$D$33*J6*Assumptions!$D$47 -> 0 | ... N27: =Assumptions!$D$33*N6*Assumptions!$D$47 -> 0 | O27: =SUM(C27:N27) -> 0
A28: Stop-loss recoveries | C28: =-Assumptions!$D$33*C6*Assumptions!$D$48 -> 0 | D28: =-Assumptions!$D$33*D6*Assumptions!$D$48 -> 0 | E28: =-Assumptions!$D$33*E6*Assumptions!$D$48 -> 0 | F28: =-Assumptions!$D$33*F6*Assumptions!$D$48 -> 0 | G28: =-Assumptions!$D$33*G6*Assumptions!$D$48 -> 0 | H28: =-Assumptions!$D$33*H6*Assumptions!$D$48 -> 0 | I28: =-Assumptions!$D$33*I6*Assumptions!$D$48 -> 0 | J28: =-Assumptions!$D$33*J6*Assumptions!$D$48 -> 0 | ... N28: =-Assumptions!$D$33*N6*Assumptions!$D$48 -> 0 | O28: =SUM(C28:N28) -> 0
A29: TOTAL PROVIDER MEDICAL COST | C29: =C26+C27+C28 -> 0 | D29: =D26+D27+D28 -> 0 | E29: =E26+E27+E28 -> 0 | F29: =F26+F27+F28 -> 0 | G29: =G26+G27+G28 -> 0 | H29: =H26+H27+H28 -> 0 | I29: =I26+I27+I28 -> 0 | J29: =J26+J27+J28 -> 0 | ... N29: =N26+N27+N28 -> 0 | O29: =SUM(C29:N29) -> 0
A31: CONTRIBUTION & RATIOS
A32: Contribution margin | C32: =C23-C29 -> 12562.5 | D32: =D23-D29 -> 12688.125 | E32: =E23-E29 -> 12815.006 | F32: =F23-F29 -> 12943.156 | G32: =G23-G29 -> 13072.588 | H32: =H23-H29 -> 13203.314 | I32: =I23-I29 -> 13335.347 | J32: =J23-J29 -> 13468.7 | ... N32: =N23-N29 -> 14015.584 | O32: =SUM(C32:N32) -> 159323.94
A33: Medical loss ratio (TCOC / premium) | C33: =IF(C6=0,0,C20/(C6*C10*C9)) -> 0.99875556 | D33: =IF(D6=0,0,D20/(D6*D10*D9)) -> 0.99361616 | E33: =IF(E6=0,0,E20/(E6*E10*E9)) -> 0.98847677 | F33: =IF(F6=0,0,F20/(F6*F10*F9)) -> 0.98333737 | G33: =IF(G6=0,0,G20/(G6*G10*G9)) -> 0.97819798 | H33: =IF(H6=0,0,H20/(H6*H10*H9)) -> 0.97305859 | I33: =IF(I6=0,0,I20/(I6*I10*I9)) -> 0.96791919 | J33: =IF(J6=0,0,J20/(J6*J10*J9)) -> 0.9627798 | ... N33: =IF(N6=0,0,N20/(N6*N10*N9)) -> 0.94222222 | O33: =O20/SUMPRODUCT(C6:N6,C10:N10,C9:N9) -> 0.96987963
A34: Contribution PMPM | C34: =IF(C6=0,0,C32/C6) -> 50 | D34: =IF(D6=0,0,D32/D6) -> 50 | E34: =IF(E6=0,0,E32/E6) -> 50 | F34: =IF(F6=0,0,F32/F6) -> 50 | G34: =IF(G6=0,0,G32/G6) -> 50 | H34: =IF(H6=0,0,H32/H6) -> 50 | I34: =IF(I6=0,0,I32/I6) -> 50 | J34: =IF(J6=0,0,J32/J6) -> 50 | ... N34: =IF(N6=0,0,N32/N6) -> 50 | O34: =O32/O6 -> 50

Sheet D. REACH
A1: CONTRACT D — ACO REACH Professional (PCCP + 50/50)
A2: ($ unless noted) | C2: Jan | D2: Feb | E2: Mar | F2: Apr | G2: May | H2: Jun | I2: Jul | J2: Aug | K2: Sep | L2: Oct | M2: Nov | N2: Dec | O2: Year 1
A3: MEMBERSHIP
A4: Members — beginning | C4: =Assumptions!$E$34 -> 200 | D4: =C5 -> 203 | E4: =D5 -> 206.045 | F4: =E5 -> 209.13567 | G4: =F5 -> 212.27271 | H4: =G5 -> 215.4568 | I4: =H5 -> 218.68865 | J4: =I5 -> 221.96898 | K4: =J5 -> 225.29852 | ... N4: =M5 -> 235.58979
A5: Members — ending | C5: =C4*(1+Assumptions!$E$35) -> 203 | D5: =D4*(1+Assumptions!$E$35) -> 206.045 | E5: =E4*(1+Assumptions!$E$35) -> 209.13567 | F5: =F4*(1+Assumptions!$E$35) -> 212.27271 | G5: =G4*(1+Assumptions!$E$35) -> 215.4568 | H5: =H4*(1+Assumptions!$E$35) -> 218.68865 | I5: =I4*(1+Assumptions!$E$35) -> 221.96898 | J5: =J4*(1+Assumptions!$E$35) -> 225.29852 | ... N5: =N4*(1+Assumptions!$E$35) -> 239.12363 | O5: =N5 -> 239.12363
A6: Member-months (avg) | C6: =AVERAGE(C4,C5) -> 201.5 | D6: =AVERAGE(D4,D5) -> 204.5225 | E6: =AVERAGE(E4,E5) -> 207.59034 | F6: =AVERAGE(F4,F5) -> 210.70419 | G6: =AVERAGE(G4,G5) -> 213.86476 | H6: =AVERAGE(H4,H5) -> 217.07273 | I6: =AVERAGE(I4,I5) -> 220.32882 | J6: =AVERAGE(J4,J5) -> 223.63375 | ... N6: =AVERAGE(N4,N5) -> 237.35671 | O6: =SUM(C6:N6) -> 2627.8041
A8: LEVERS — RISK & TCOC
A9: RAF (risk score, Yr-1 cohort) | C9: =Assumptions!$E$36*Assumptions!$B$52 -> 0.945 | D9: =Assumptions!$E$36*Assumptions!$B$52 -> 0.945 | E9: =Assumptions!$E$36*Assumptions!$B$52 -> 0.945 | F9: =Assumptions!$E$36*Assumptions!$B$52 -> 0.945 | G9: =Assumptions!$E$36*Assumptions!$B$52 -> 0.945 | H9: =Assumptions!$E$36*Assumptions!$B$52 -> 0.945 | I9: =Assumptions!$E$36*Assumptions!$B$52 -> 0.945 | J9: =Assumptions!$E$36*Assumptions!$B$52 -> 0.945 | ... N9: =Assumptions!$E$36*Assumptions!$B$52 -> 0.945
A10: Premium / benchmark PMPM | C10: =Assumptions!$E$37 -> 1150 | D10: =Assumptions!$E$37 -> 1150 | E10: =Assumptions!$E$37 -> 1150 | F10: =Assumptions!$E$37 -> 1150 | G10: =Assumptions!$E$37 -> 1150 | H10: =Assumptions!$E$37 -> 1150 | I10: =Assumptions!$E$37 -> 1150 | J10: =Assumptions!$E$37 -> 1150 | ... N10: =Assumptions!$E$37 -> 1150
A11: New-clinic TCOC factor | C11: =Assumptions!$B$9+(Assumptions!$B$10-Assumptions!$B$9)*(0)/11 -> 1.06 | D11: =Assumptions!$B$9+(Assumptions!$B$10-Assumptions!$B$9)*(1)/11 -> 1.0545455 | E11: =Assumptions!$B$9+(Assumptions!$B$10-Assumptions!$B$9)*(2)/11 -> 1.0490909 | F11: =Assumptions!$B$9+(Assumptions!$B$10-Assumptions!$B$9)*(3)/11 -> 1.0436364 | G11: =Assumptions!$B$9+(Assumptions!$B$10-Assumptions!$B$9)*(4)/11 -> 1.0381818 | H11: =Assumptions!$B$9+(Assumptions!$B$10-Assumptions!$B$9)*(5)/11 -> 1.0327273 | I11: =Assumptions!$B$9+(Assumptions!$B$10-Assumptions!$B$9)*(6)/11 -> 1.0272727 | J11: =Assumptions!$B$9+(Assumptions!$B$10-Assumptions!$B$9)*(7)/11 -> 1.0218182 | K11: =Assumptions!$B$9+(Assumptions!$B$10-Assumptions!$B$9)*(8)/11 -> 1.0163636 | L11: =Assumptions!$B$9+(Assumptions!$B$10-Assumptions!$B$9)*(9)/11 -> 1.0109091 | M11: =Assumptions!$B$9+(Assumptions!$B$10-Assumptions!$B$9)*(10)/11 -> 1.0054545 | N11: =Assumptions!$B$9+(Assumptions!$B$10-Assumptions!$B$9)*(11)/11 -> 1
A12: Actual TCOC PMPM | C12: =Assumptions!$E$46*C11 -> 1070.6 | D12: =Assumptions!$E$46*D11 -> 1065.0909 | E12: =Assumptions!$E$46*E11 -> 1059.5818 | F12: =Assumptions!$E$46*F11 -> 1054.0727 | G12: =Assumptions!$E$46*G11 -> 1048.5636 | H12: =Assumptions!$E$46*H11 -> 1043.0545 | I12: =Assumptions!$E$46*I11 -> 1037.5455 | J12: =Assumptions!$E$46*J11 -> 1032.0364 | ... N12: =Assumptions!$E$46*N11 -> 1010
A14: REVENUE
A15: Global capitation | C15: =C6*C10*C9*Assumptions!$E$38 -> 0 | D15: =D6*D10*D9*Assumptions!$E$38 -> 0 | E15: =E6*E10*E9*Assumptions!$E$38 -> 0 | F15: =F6*F10*F9*Assumptions!$E$38 -> 0 | G15: =G6*G10*G9*Assumptions!$E$38 -> 0 | H15: =H6*H10*H9*Assumptions!$E$38 -> 0 | I15: =I6*I10*I9*Assumptions!$E$38 -> 0 | J15: =J6*J10*J9*Assumptions!$E$38 -> 0 | ... N15: =N6*N10*N9*Assumptions!$E$38 -> 0 | O15: =SUM(C15:N15) -> 0
A16: Care management | C16: =C6*Assumptions!$E$39 -> 0 | D16: =D6*Assumptions!$E$39 -> 0 | E16: =E6*Assumptions!$E$39 -> 0 | F16: =F6*Assumptions!$E$39 -> 0 | G16: =G6*Assumptions!$E$39 -> 0 | H16: =H6*Assumptions!$E$39 -> 0 | I16: =I6*Assumptions!$E$39 -> 0 | J16: =J6*Assumptions!$E$39 -> 0 | ... N16: =N6*Assumptions!$E$39 -> 0 | O16: =SUM(C16:N16) -> 0
A17: Primary care cap (PCCP) | C17: =C6*Assumptions!$E$40 -> 16120 | D17: =D6*Assumptions!$E$40 -> 16361.8 | E17: =E6*Assumptions!$E$40 -> 16607.227 | F17: =F6*Assumptions!$E$40 -> 16856.335 | G17: =G6*Assumptions!$E$40 -> 17109.18 | H17: =H6*Assumptions!$E$40 -> 17365.818 | I17: =I6*Assumptions!$E$40 -> 17626.305 | J17: =J6*Assumptions!$E$40 -> 17890.7 | ... N17: =N6*Assumptions!$E$40 -> 18988.537 | O17: =SUM(C17:N17) -> 210224.33
A18: FFS own services | C18: =C6*Assumptions!$E$41 -> 0 | D18: =D6*Assumptions!$E$41 -> 0 | E18: =E6*Assumptions!$E$41 -> 0 | F18: =F6*Assumptions!$E$41 -> 0 | G18: =G6*Assumptions!$E$41 -> 0 | H18: =H6*Assumptions!$E$41 -> 0 | I18: =I6*Assumptions!$E$41 -> 0 | J18: =J6*Assumptions!$E$41 -> 0 | ... N18: =N6*Assumptions!$E$41 -> 0 | O18: =SUM(C18:N18) -> 0
A19: Benchmark / target TCOC (memo) | C19: =C6*C10*C9*Assumptions!$E$42 -> 214600.52 | D19: =D6*D10*D9*Assumptions!$E$42 -> 217819.53 | E19: =E6*E10*E9*Assumptions!$E$42 -> 221086.82 | F19: =F6*F10*F9*Assumptions!$E$42 -> 224403.13 | G19: =G6*G10*G9*Assumptions!$E$42 -> 227769.17 | H19: =H6*H10*H9*Assumptions!$E$42 -> 231185.71 | I19: =I6*I10*I9*Assumptions!$E$42 -> 234653.5 | J19: =J6*J10*J9*Assumptions!$E$42 -> 238173.3 | ... N19: =N6*N10*N9*Assumptions!$E$42 -> 252788.46 | O19: =SUM(C19:N19) -> 2798650.8
A20: Actual TCOC (memo) | C20: =C6*C12 -> 215725.9 | D20: =D6*D12 -> 217835.06 | E20: =E6*E12 -> 219958.95 | F20: =F6*F12 -> 222097.54 | G20: =G6*G12 -> 224250.81 | H20: =H6*H12 -> 226418.69 | I20: =I6*I12 -> 228601.16 | J20: =J6*J12 -> 230798.16 | ... N20: =N6*N12 -> 239730.28 | O20: =SUM(C20:N20) -> 2731137.5
A21: Gross savings vs benchmark (memo) | C21: =C19-C20 -> -1125.3775 | D21: =D19-D20 -> -15.525117 | E21: =E19-E20 -> 1127.876 | F21: =F19-F20 -> 2305.5827 | G21: =G19-G20 -> 3518.3669 | H21: =H19-H20 -> 4767.0157 | I21: =I19-I20 -> 6052.3325 | J21: =J19-J20 -> 7375.1361 | ... N21: =N19-N20 -> 13058.179 | O21: =SUM(C21:N21) -> 67513.318
A22: Shared savings / (loss) settlement | C22: =IF(Assumptions!$E$33=1,0,IF(C21>=0,C21*Assumptions!$E$43,C21*Assumptions!$E$44*Assumptions!$E$45)) -> -562.68875 | D22: =IF(Assumptions!$E$33=1,0,IF(D21>=0,D21*Assumptions!$E$43,D21*Assumptions!$E$44*Assumptions!$E$45)) -> -7.7625585 | E22: =IF(Assumptions!$E$33=1,0,IF(E21>=0,E21*Assumptions!$E$43,E21*Assumptions!$E$44*Assumptions!$E$45)) -> 563.93802 | F22: =IF(Assumptions!$E$33=1,0,IF(F21>=0,F21*Assumptions!$E$43,F21*Assumptions!$E$44*Assumptions!$E$45)) -> 1152.7914 | G22: =IF(Assumptions!$E$33=1,0,IF(G21>=0,G21*Assumptions!$E$43,G21*Assumptions!$E$44*Assumptions!$E$45)) -> 1759.1834 | H22: =IF(Assumptions!$E$33=1,0,IF(H21>=0,H21*Assumptions!$E$43,H21*Assumptions!$E$44*Assumptions!$E$45)) -> 2383.5079 | I22: =IF(Assumptions!$E$33=1,0,IF(I21>=0,I21*Assumptions!$E$43,I21*Assumptions!$E$44*Assumptions!$E$45)) -> 3026.1662 | J22: =IF(Assumptions!$E$33=1,0,IF(J21>=0,J21*Assumptions!$E$43,J21*Assumptions!$E$44*Assumptions!$E$45)) -> 3687.5681 | ... N22: =IF(Assumptions!$E$33=1,0,IF(N21>=0,N21*Assumptions!$E$43,N21*Assumptions!$E$44*Assumptions!$E$45)) -> 6529.0897 | O22: =SUM(C22:N22) -> 33756.659
A23: TOTAL PROVIDER REVENUE | C23: =C15+C16+C17+C18+C22 -> 15557.311 | D23: =D15+D16+D17+D18+D22 -> 16354.037 | E23: =E15+E16+E17+E18+E22 -> 17171.165 | F23: =F15+F16+F17+F18+F22 -> 18009.127 | G23: =G15+G16+G17+G18+G22 -> 18868.364 | H23: =H15+H16+H17+H18+H22 -> 19749.326 | I23: =I15+I16+I17+I18+I22 -> 20652.472 | J23: =J15+J16+J17+J18+J22 -> 21578.268 | ... N23: =N15+N16+N17+N18+N22 -> 25517.627 | O23: =SUM(C23:N23) -> 243980.99
A25: PROVIDER MEDICAL COST (cash-bearing)
A26: Medical claims (full-cap only) | C26: =Assumptions!$E$33*C20 -> 0 | D26: =Assumptions!$E$33*D20 -> 0 | E26: =Assumptions!$E$33*E20 -> 0 | F26: =Assumptions!$E$33*F20 -> 0 | G26: =Assumptions!$E$33*G20 -> 0 | H26: =Assumptions!$E$33*H20 -> 0 | I26: =Assumptions!$E$33*I20 -> 0 | J26: =Assumptions!$E$33*J20 -> 0 | ... N26: =Assumptions!$E$33*N20 -> 0 | O26: =SUM(C26:N26) -> 0
A27: Stop-loss premium | C27: =Assumptions!$E$33*C6*Assumptions!$E$47 -> 0 | D27: =Assumptions!$E$33*D6*Assumptions!$E$47 -> 0 | E27: =Assumptions!$E$33*E6*Assumptions!$E$47 -> 0 | F27: =Assumptions!$E$33*F6*Assumptions!$E$47 -> 0 | G27: =Assumptions!$E$33*G6*Assumptions!$E$47 -> 0 | H27: =Assumptions!$E$33*H6*Assumptions!$E$47 -> 0 | I27: =Assumptions!$E$33*I6*Assumptions!$E$47 -> 0 | J27: =Assumptions!$E$33*J6*Assumptions!$E$47 -> 0 | ... N27: =Assumptions!$E$33*N6*Assumptions!$E$47 -> 0 | O27: =SUM(C27:N27) -> 0
A28: Stop-loss recoveries | C28: =-Assumptions!$E$33*C6*Assumptions!$E$48 -> 0 | D28: =-Assumptions!$E$33*D6*Assumptions!$E$48 -> 0 | E28: =-Assumptions!$E$33*E6*Assumptions!$E$48 -> 0 | F28: =-Assumptions!$E$33*F6*Assumptions!$E$48 -> 0 | G28: =-Assumptions!$E$33*G6*Assumptions!$E$48 -> 0 | H28: =-Assumptions!$E$33*H6*Assumptions!$E$48 -> 0 | I28: =-Assumptions!$E$33*I6*Assumptions!$E$48 -> 0 | J28: =-Assumptions!$E$33*J6*Assumptions!$E$48 -> 0 | ... N28: =-Assumptions!$E$33*N6*Assumptions!$E$48 -> 0 | O28: =SUM(C28:N28) -> 0
A29: TOTAL PROVIDER MEDICAL COST | C29: =C26+C27+C28 -> 0 | D29: =D26+D27+D28 -> 0 | E29: =E26+E27+E28 -> 0 | F29: =F26+F27+F28 -> 0 | G29: =G26+G27+G28 -> 0 | H29: =H26+H27+H28 -> 0 | I29: =I26+I27+I28 -> 0 | J29: =J26+J27+J28 -> 0 | ... N29: =N26+N27+N28 -> 0 | O29: =SUM(C29:N29) -> 0
A31: CONTRIBUTION & RATIOS
A32: Contribution margin | C32: =C23-C29 -> 15557.311 | D32: =D23-D29 -> 16354.037 | E32: =E23-E29 -> 17171.165 | F32: =F23-F29 -> 18009.127 | G32: =G23-G29 -> 18868.364 | H32: =H23-H29 -> 19749.326 | I32: =I23-I29 -> 20652.472 | J32: =J23-J29 -> 21578.268 | ... N32: =N23-N29 -> 25517.627 | O32: =SUM(C32:N32) -> 243980.99
A33: Medical loss ratio (TCOC / premium) | C33: =IF(C6=0,0,C20/(C6*C10*C9)) -> 0.98513918 | D33: =IF(D6=0,0,D20/(D6*D10*D9)) -> 0.98006985 | E33: =IF(E6=0,0,E20/(E6*E10*E9)) -> 0.97500052 | F33: =IF(F6=0,0,F20/(F6*F10*F9)) -> 0.9699312 | G33: =IF(G6=0,0,G20/(G6*G10*G9)) -> 0.96486187 | H33: =IF(H6=0,0,H20/(H6*H10*H9)) -> 0.95979254 | I33: =IF(I6=0,0,I20/(I6*I10*I9)) -> 0.95472322 | J33: =IF(J6=0,0,J20/(J6*J10*J9)) -> 0.94965389 | ... N33: =IF(N6=0,0,N20/(N6*N10*N9)) -> 0.92937658 | O33: =O20/SUMPRODUCT(C6:N6,C10:N10,C9:N9) -> 0.95635895
A34: Contribution PMPM | C34: =IF(C6=0,0,C32/C6) -> 77.2075 | D34: =IF(D6=0,0,D32/D6) -> 79.962045 | E34: =IF(E6=0,0,E32/E6) -> 82.716591 | F34: =IF(F6=0,0,F32/F6) -> 85.471136 | G34: =IF(G6=0,0,G32/G6) -> 88.225682 | H34: =IF(H6=0,0,H32/H6) -> 90.980227 | I34: =IF(I6=0,0,I32/I6) -> 93.734773 | J34: =IF(J6=0,0,J32/J6) -> 96.489318 | ... N34: =IF(N6=0,0,N32/N6) -> 107.5075 | O34: =O32/O6 -> 92.845957

Sheet P&L (Monthly)
A1: CONSOLIDATED P&L — Year 1 (Monthly)
C2: Jan | D2: Feb | E2: Mar | F2: Apr | G2: May | H2: Jun | I2: Jul | J2: Aug | K2: Sep | L2: Oct | M2: Nov | N2: Dec | O2: Year 1
A3: MEMBERSHIP
A4: Member-months (avg) | C4: ='A. Full Cap'!C6+'B. Two-Sided'!C6+'C. Upside'!C6+'D. REACH'!C6 -> 4523 | D4: ='A. Full Cap'!D6+'B. Two-Sided'!D6+'C. Upside'!D6+'D. REACH'!D6 -> 4569.2375 | E4: ='A. Full Cap'!E6+'B. Two-Sided'!E6+'C. Upside'!E6+'D. REACH'!E6 -> 4615.9525 | F4: ='A. Full Cap'!F6+'B. Two-Sided'!F6+'C. Upside'!F6+'D. REACH'!F6 -> 4663.15 | G4: ='A. Full Cap'!G6+'B. Two-Sided'!G6+'C. Upside'!G6+'D. REACH'!G6 -> 4710.835 | H4: ='A. Full Cap'!H6+'B. Two-Sided'!H6+'C. Upside'!H6+'D. REACH'!H6 -> 4759.0127 | I4: ='A. Full Cap'!I6+'B. Two-Sided'!I6+'C. Upside'!I6+'D. REACH'!I6 -> 4807.6881 | J4: ='A. Full Cap'!J6+'B. Two-Sided'!J6+'C. Upside'!J6+'D. REACH'!J6 -> 4856.8667 | ... N4: ='A. Full Cap'!N6+'B. Two-Sided'!N6+'C. Upside'!N6+'D. REACH'!N6 -> 5058.7175 | O4: =SUM(C4:N4) -> 57435.241
A6: REVENUE
A7: Global capitation | C7: ='A. Full Cap'!C15+'B. Two-Sided'!C15+'C. Upside'!C15+'D. REACH'!C15 -> 4759261.9 | D7: ='A. Full Cap'!D15+'B. Two-Sided'!D15+'C. Upside'!D15+'D. REACH'!D15 -> 4806854.5 | E7: ='A. Full Cap'!E15+'B. Two-Sided'!E15+'C. Upside'!E15+'D. REACH'!E15 -> 4854923.1 | F7: ='A. Full Cap'!F15+'B. Two-Sided'!F15+'C. Upside'!F15+'D. REACH'!F15 -> 4903472.3 | G7: ='A. Full Cap'!G15+'B. Two-Sided'!G15+'C. Upside'!G15+'D. REACH'!G15 -> 4952507 | H7: ='A. Full Cap'!H15+'B. Two-Sided'!H15+'C. Upside'!H15+'D. REACH'!H15 -> 5002032.1 | I7: ='A. Full Cap'!I15+'B. Two-Sided'!I15+'C. Upside'!I15+'D. REACH'!I15 -> 5052052.4 | J7: ='A. Full Cap'!J15+'B. Two-Sided'!J15+'C. Upside'!J15+'D. REACH'!J15 -> 5102573 | ... N7: ='A. Full Cap'!N15+'B. Two-Sided'!N15+'C. Upside'!N15+'D. REACH'!N15 -> 5309757.9 | O7: =SUM(C7:N7) -> 60359354
A8: Care management | C8: ='A. Full Cap'!C16+'B. Two-Sided'!C16+'C. Upside'!C16+'D. REACH'!C16 -> 24873.75 | D8: ='A. Full Cap'!D16+'B. Two-Sided'!D16+'C. Upside'!D16+'D. REACH'!D16 -> 25122.487 | E8: ='A. Full Cap'!E16+'B. Two-Sided'!E16+'C. Upside'!E16+'D. REACH'!E16 -> 25373.712 | F8: ='A. Full Cap'!F16+'B. Two-Sided'!F16+'C. Upside'!F16+'D. REACH'!F16 -> 25627.449 | G8: ='A. Full Cap'!G16+'B. Two-Sided'!G16+'C. Upside'!G16+'D. REACH'!G16 -> 25883.724 | H8: ='A. Full Cap'!H16+'B. Two-Sided'!H16+'C. Upside'!H16+'D. REACH'!H16 -> 26142.561 | I8: ='A. Full Cap'!I16+'B. Two-Sided'!I16+'C. Upside'!I16+'D. REACH'!I16 -> 26403.987 | J8: ='A. Full Cap'!J16+'B. Two-Sided'!J16+'C. Upside'!J16+'D. REACH'!J16 -> 26668.027 | ... N8: ='A. Full Cap'!N16+'B. Two-Sided'!N16+'C. Upside'!N16+'D. REACH'!N16 -> 27750.856 | O8: =SUM(C8:N8) -> 315461.41
A9: Primary care cap (PCCP) | C9: ='A. Full Cap'!C17+'B. Two-Sided'!C17+'C. Upside'!C17+'D. REACH'!C17 -> 16120 | D9: ='A. Full Cap'!D17+'B. Two-Sided'!D17+'C. Upside'!D17+'D. REACH'!D17 -> 16361.8 | E9: ='A. Full Cap'!E17+'B. Two-Sided'!E17+'C. Upside'!E17+'D. REACH'!E17 -> 16607.227 | F9: ='A. Full Cap'!F17+'B. Two-Sided'!F17+'C. Upside'!F17+'D. REACH'!F17 -> 16856.335 | G9: ='A. Full Cap'!G17+'B. Two-Sided'!G17+'C. Upside'!G17+'D. REACH'!G17 -> 17109.18 | H9: ='A. Full Cap'!H17+'B. Two-Sided'!H17+'C. Upside'!H17+'D. REACH'!H17 -> 17365.818 | I9: ='A. Full Cap'!I17+'B. Two-Sided'!I17+'C. Upside'!I17+'D. REACH'!I17 -> 17626.305 | J9: ='A. Full Cap'!J17+'B. Two-Sided'!J17+'C. Upside'!J17+'D. REACH'!J17 -> 17890.7 | ... N9: ='A. Full Cap'!N17+'B. Two-Sided'!N17+'C. Upside'!N17+'D. REACH'!N17 -> 18988.537 | O9: =SUM(C9:N9) -> 210224.33
A10: FFS own services | C10: ='A. Full Cap'!C18+'B. Two-Sided'!C18+'C. Upside'!C18+'D. REACH'!C18 -> 12562.5 | D10: ='A. Full Cap'!D18+'B. Two-Sided'!D18+'C. Upside'!D18+'D. REACH'!D18 -> 12688.125 | E10: ='A. Full Cap'!E18+'B. Two-Sided'!E18+'C. Upside'!E18+'D. REACH'!E18 -> 12815.006 | F10: ='A. Full Cap'!F18+'B. Two-Sided'!F18+'C. Upside'!F18+'D. REACH'!F18 -> 12943.156 | G10: ='A. Full Cap'!G18+'B. Two-Sided'!G18+'C. Upside'!G18+'D. REACH'!G18 -> 13072.588 | H10: ='A. Full Cap'!H18+'B. Two-Sided'!H18+'C. Upside'!H18+'D. REACH'!H18 -> 13203.314 | I10: ='A. Full Cap'!I18+'B. Two-Sided'!I18+'C. Upside'!I18+'D. REACH'!I18 -> 13335.347 | J10: ='A. Full Cap'!J18+'B. Two-Sided'!J18+'C. Upside'!J18+'D. REACH'!J18 -> 13468.7 | ... N10: ='A. Full Cap'!N18+'B. Two-Sided'!N18+'C. Upside'!N18+'D. REACH'!N18 -> 14015.584 | O10: =SUM(C10:N10) -> 159323.94
A11: Shared savings / (loss) | C11: ='A. Full Cap'!C22+'B. Two-Sided'!C22+'C. Upside'!C22+'D. REACH'!C22 -> -15156.796 | D11: ='A. Full Cap'!D22+'B. Two-Sided'!D22+'C. Upside'!D22+'D. REACH'!D22 -> -13352.579 | E11: ='A. Full Cap'!E22+'B. Two-Sided'!E22+'C. Upside'!E22+'D. REACH'!E22 -> -11505.142 | F11: ='A. Full Cap'!F22+'B. Two-Sided'!F22+'C. Upside'!F22+'D. REACH'!F22 -> -9613.7026 | G11: ='A. Full Cap'!G22+'B. Two-Sided'!G22+'C. Upside'!G22+'D. REACH'!G22 -> -7677.4662 | H11: ='A. Full Cap'!H22+'B. Two-Sided'!H22+'C. Upside'!H22+'D. REACH'!H22 -> -5695.6238 | I11: ='A. Full Cap'!I22+'B. Two-Sided'!I22+'C. Upside'!I22+'D. REACH'!I22 -> -3667.3535 | J11: ='A. Full Cap'!J22+'B. Two-Sided'!J22+'C. Upside'!J22+'D. REACH'!J22 -> -1591.8196 | ... N11: ='A. Full Cap'!N22+'B. Two-Sided'!N22+'C. Upside'!N22+'D. REACH'!N22 -> 7200.1559 | O11: =SUM(C11:N11) -> -52897.118
A12: Total revenue | C12: =SUM(C7:C11) -> 4797661.4 | D12: =SUM(D7:D11) -> 4847674.4 | E12: =SUM(E7:E11) -> 4898213.9 | F12: =SUM(F7:F11) -> 4949285.6 | G12: =SUM(G7:G11) -> 5000895.1 | H12: =SUM(H7:H11) -> 5053048.2 | I12: =SUM(I7:I11) -> 5105750.7 | J12: =SUM(J7:J11) -> 5159008.6 | ... O12: =SUM(O7:O11) -> 60991466
A14: MEDICAL COST (provider-borne)
A15: Medical claims (full-cap) | C15: ='A. Full Cap'!C26+'B. Two-Sided'!C26+'C. Upside'!C26+'D. REACH'!C26 -> 4371991.2 | D15: ='A. Full Cap'!D26+'B. Two-Sided'!D26+'C. Upside'!D26+'D. REACH'!D26 -> 4392988.8 | E15: ='A. Full Cap'!E26+'B. Two-Sided'!E26+'C. Upside'!E26+'D. REACH'!E26 -> 4413969.1 | F15: ='A. Full Cap'!F26+'B. Two-Sided'!F26+'C. Upside'!F26+'D. REACH'!F26 -> 4434929.7 | G15: ='A. Full Cap'!G26+'B. Two-Sided'!G26+'C. Upside'!G26+'D. REACH'!G26 -> 4455868.1 | H15: ='A. Full Cap'!H26+'B. Two-Sided'!H26+'C. Upside'!H26+'D. REACH'!H26 -> 4476781.8 | I15: ='A. Full Cap'!I26+'B. Two-Sided'!I26+'C. Upside'!I26+'D. REACH'!I26 -> 4497668.2 | J15: ='A. Full Cap'!J26+'B. Two-Sided'!J26+'C. Upside'!J26+'D. REACH'!J26 -> 4518524.7 | ... N15: ='A. Full Cap'!N26+'B. Two-Sided'!N26+'C. Upside'!N26+'D. REACH'!N26 -> 4601596.4 | O15: =SUM(C15:N15) -> 53844690
A16: Stop-loss premium | C16: ='A. Full Cap'!C27+'B. Two-Sided'!C27+'C. Upside'!C27+'D. REACH'!C27 -> 126630 | D16: ='A. Full Cap'!D27+'B. Two-Sided'!D27+'C. Upside'!D27+'D. REACH'!D27 -> 127896.3 | E16: ='A. Full Cap'!E27+'B. Two-Sided'!E27+'C. Upside'!E27+'D. REACH'!E27 -> 129175.26 | F16: ='A. Full Cap'!F27+'B. Two-Sided'!F27+'C. Upside'!F27+'D. REACH'!F27 -> 130467.02 | G16: ='A. Full Cap'!G27+'B. Two-Sided'!G27+'C. Upside'!G27+'D. REACH'!G27 -> 131771.69 | H16: ='A. Full Cap'!H27+'B. Two-Sided'!H27+'C. Upside'!H27+'D. REACH'!H27 -> 133089.4 | I16: ='A. Full Cap'!I27+'B. Two-Sided'!I27+'C. Upside'!I27+'D. REACH'!I27 -> 134420.3 | J16: ='A. Full Cap'!J27+'B. Two-Sided'!J27+'C. Upside'!J27+'D. REACH'!J27 -> 135764.5 | ... N16: ='A. Full Cap'!N27+'B. Two-Sided'!N27+'C. Upside'!N27+'D. REACH'!N27 -> 141277.08 | O16: =SUM(C16:N16) -> 1605985.4
A17: Stop-loss recoveries | C17: ='A. Full Cap'!C28+'B. Two-Sided'!C28+'C. Upside'!C28+'D. REACH'!C28 -> -94068 | D17: ='A. Full Cap'!D28+'B. Two-Sided'!D28+'C. Upside'!D28+'D. REACH'!D28 -> -95008.68 | E17: ='A. Full Cap'!E28+'B. Two-Sided'!E28+'C. Upside'!E28+'D. REACH'!E28 -> -95958.767 | F17: ='A. Full Cap'!F28+'B. Two-Sided'!F28+'C. Upside'!F28+'D. REACH'!F28 -> -96918.354 | G17: ='A. Full Cap'!G28+'B. Two-Sided'!G28+'C. Upside'!G28+'D. REACH'!G28 -> -97887.538 | H17: ='A. Full Cap'!H28+'B. Two-Sided'!H28+'C. Upside'!H28+'D. REACH'!H28 -> -98866.413 | I17: ='A. Full Cap'!I28+'B. Two-Sided'!I28+'C. Upside'!I28+'D. REACH'!I28 -> -99855.078 | J17: ='A. Full Cap'!J28+'B. Two-Sided'!J28+'C. Upside'!J28+'D. REACH'!J28 -> -100853.63 | ... N17: ='A. Full Cap'!N28+'B. Two-Sided'!N28+'C. Upside'!N28+'D. REACH'!N28 -> -104948.69 | O17: =SUM(C17:N17) -> -1193017.7
A18: Total medical cost | C18: =SUM(C15:C17) -> 4404553.2 | D18: =SUM(D15:D17) -> 4425876.4 | E18: =SUM(E15:E17) -> 4447185.6 | F18: =SUM(F15:F17) -> 4468478.3 | G18: =SUM(G15:G17) -> 4489752.3 | H18: =SUM(H15:H17) -> 4511004.8 | I18: =SUM(I15:I17) -> 4532233.4 | J18: =SUM(J15:J17) -> 4553435.5 | ... O18: =SUM(O15:O17) -> 54257658
A20: MEDICAL MARGIN (contribution) | C20: =C12-C18 -> 393108.17 | D20: =D12-D18 -> 421798 | E20: =E12-E18 -> 451028.33 | F20: =F12-F18 -> 480807.21 | G20: =G12-G18 -> 511142.81 | H20: =H12-H18 -> 542043.37 | I20: =I12-I18 -> 573517.28 | J20: =J12-J18 -> 605573.03 | ... O20: =O12-O18 -> 6733808.1
A22: CLINIC OPERATING EXPENSE
A23: Fixed clinic opex | C23: =Assumptions!$B$14 -> 380000 | D23: =Assumptions!$B$14 -> 380000 | E23: =Assumptions!$B$14 -> 380000 | F23: =Assumptions!$B$14 -> 380000 | G23: =Assumptions!$B$14 -> 380000 | H23: =Assumptions!$B$14 -> 380000 | I23: =Assumptions!$B$14 -> 380000 | J23: =Assumptions!$B$14 -> 380000 | ... N23: =Assumptions!$B$14 -> 380000 | O23: =SUM(C23:N23) -> 4560000
A24: Care management (variable) | C24: =C4*Assumptions!$B$15 -> 81414 | D24: =D4*Assumptions!$B$15 -> 82246.275 | E24: =E4*Assumptions!$B$15 -> 83087.145 | F24: =F4*Assumptions!$B$15 -> 83936.699 | G24: =G4*Assumptions!$B$15 -> 84795.03 | H24: =H4*Assumptions!$B$15 -> 85662.228 | I24: =I4*Assumptions!$B$15 -> 86538.387 | J24: =J4*Assumptions!$B$15 -> 87423.6 | ... N24: =N4*Assumptions!$B$15 -> 91056.914 | O24: =SUM(C24:N24) -> 1033834.3
A25: G&A / corporate | C25: =Assumptions!$B$16 -> 120000 | D25: =Assumptions!$B$16 -> 120000 | E25: =Assumptions!$B$16 -> 120000 | F25: =Assumptions!$B$16 -> 120000 | G25: =Assumptions!$B$16 -> 120000 | H25: =Assumptions!$B$16 -> 120000 | I25: =Assumptions!$B$16 -> 120000 | J25: =Assumptions!$B$16 -> 120000 | ... N25: =Assumptions!$B$16 -> 120000 | O25: =SUM(C25:N25) -> 1440000
A26: Total clinic opex | C26: =SUM(C23:C25) -> 581414 | D26: =SUM(D23:D25) -> 582246.28 | E26: =SUM(E23:E25) -> 583087.14 | F26: =SUM(F23:F25) -> 583936.7 | G26: =SUM(G23:G25) -> 584795.03 | H26: =SUM(H23:H25) -> 585662.23 | I26: =SUM(I23:I25) -> 586538.39 | J26: =SUM(J23:J25) -> 587423.6 | ... O26: =SUM(O23:O25) -> 7033834.3
A28: EBITDA | C28: =C20-C26 -> -188305.83 | D28: =D20-D26 -> -160448.28 | E28: =E20-E26 -> -132058.82 | F28: =F20-F26 -> -103129.49 | G28: =G20-G26 -> -73652.224 | H28: =H20-H26 -> -43618.857 | I28: =I20-I26 -> -13021.102 | J28: =J20-J26 -> 18149.434 | ... O28: =O20-O26 -> -300026.21
A29: EBITDA margin | C29: =IF(C12=0,0,C28/C12) -> -0.039249503 | D29: =IF(D12=0,0,D28/D12) -> -0.03309799 | E29: =IF(E12=0,0,E28/E12) -> -0.026960606 | F29: =IF(F12=0,0,F28/F12) -> -0.020837247 | G29: =IF(G12=0,0,G28/G12) -> -0.014727808 | H29: =IF(H12=0,0,H28/H12) -> -0.008632187 | I29: =IF(I12=0,0,I28/I12) -> -0.0025502817 | J29: =IF(J12=0,0,J28/J12) -> 0.0035180082 | ... O29: =IF(O12=0,0,O28/O12) -> -0.0049191506
A30: Medical margin PMPM | C30: =IF(C4=0,0,C20/C4) -> 86.913149 | D30: =IF(D4=0,0,D20/D4) -> 92.312557 | E30: =IF(E4=0,0,E20/E4) -> 97.710782 | F30: =IF(F4=0,0,F20/F4) -> 103.10782 | G30: =IF(G4=0,0,G20/G4) -> 108.50365 | H30: =IF(H4=0,0,H20/H4) -> 113.89828 | I30: =IF(I4=0,0,I20/I4) -> 119.2917 | J30: =IF(J4=0,0,J20/J4) -> 124.68389 | ... O30: =IF(O4=0,0,O20/O4) -> 117.24175

Sheet Cash Flow
A1: CASH FLOW — Year 1 (Monthly)
A2: Full-cap dynamic: capitation received prospectively, claims paid in arrears (lag), IBNR float builds.
C3: Jan | D3: Feb | E3: Mar | F3: Apr | G3: May | H3: Jun | I3: Jul | J3: Aug | K3: Sep | L3: Oct | M3: Nov | N3: Dec | O3: Year 1
A4: OPERATING CASH IN
